Workbook

Sheet 업그레이드
B2: 식별 순번 | C2: 식별 Enum | D2: 레벨 | E2: 항목 | F2: 수치 | G2: 수치 타입 | H2: 가격 타입 | I2: 가격 수치 | J2: 기타 설명
B3: 1 | C3: ATT | D3: 1 | E3: 공격력 | F3: ='밸런스 조정'!$C$3+'밸런스 조정'!$D$3*D3 -> 4 | G3: value | H3: Coin | I3: =ROUND('밸런스 조정'!$E$3+'밸런스 조정'!$F$3*(D3-1)+'밸런스 조정'!$C$69*MAX(0,D3-3)^2,0) -> 10 | J3: 기본 공격력 증가
B4: 1 | C4: ATT | D4: 2 | E4: 공격력 | F4: ='밸런스 조정'!$C$3+'밸런스 조정'!$D$3*D4 -> 8 | G4: value | H4: Coin | I4: =ROUND('밸런스 조정'!$E$3+'밸런스 조정'!$F$3*(D4-1)+'밸런스 조정'!$C$69*MAX(0,D4-3)^2,0) -> 15 | J4: 기본 공격력 증가
B5: 1 | C5: ATT | D5: 3 | E5: 공격력 | F5: ='밸런스 조정'!$C$3+'밸런스 조정'!$D$3*D5 -> 12 | G5: value | H5: Coin | I5: =ROUND('밸런스 조정'!$E$3+'밸런스 조정'!$F$3*(D5-1)+'밸런스 조정'!$C$69*MAX(0,D5-3)^2,0) -> 20 | J5: 기본 공격력 증가
B6: 1 | C6: ATT | D6: 4 | E6: 공격력 | F6: ='밸런스 조정'!$C$3+'밸런스 조정'!$D$3*D6 -> 16 | G6: value | H6: Coin | I6: =ROUND('밸런스 조정'!$E$3+'밸런스 조정'!$F$3*(D6-1)+'밸런스 조정'!$C$69*MAX(0,D6-3)^2,0) -> 27 | J6: 기본 공격력 증가
B7: 1 | C7: ATT | D7: 5 | E7: 공격력 | F7: ='밸런스 조정'!$C$3+'밸런스 조정'!$D$3*D7 -> 20 | G7: value | H7: Coin | I7: =ROUND('밸런스 조정'!$E$3+'밸런스 조정'!$F$3*(D7-1)+'밸런스 조정'!$C$69*MAX(0,D7-3)^2,0) -> 38 | J7: 기본 공격력 증가
B8: 1 | C8: ATT | D8: 6 | E8: 공격력 | F8: ='밸런스 조정'!$C$3+'밸런스 조정'!$D$3*D8 -> 24 | G8: value | H8: Coin | I8: =ROUND('밸런스 조정'!$E$3+'밸런스 조정'!$F$3*(D8-1)+'밸런스 조정'!$C$69*MAX(0,D8-3)^2,0) -> 53 | J8: 기본 공격력 증가
B9: 1 | C9: ATT | D9: 7 | E9: 공격력 | F9: ='밸런스 조정'!$C$3+'밸런스 조정'!$D$3*D9 -> 28 | G9: value | H9: Coin | I9: =ROUND('밸런스 조정'!$E$3+'밸런스 조정'!$F$3*(D9-1)+'밸런스 조정'!$C$69*MAX(0,D9-3)^2,0) -> 72 | J9: 기본 공격력 증가
B10: 1 | C10: ATT | D10: 8 | E10: 공격력 | F10: ='밸런스 조정'!$C$3+'밸런스 조정'!$D$3*D10 -> 32 | G10: value | H10: Coin | I10: =ROUND('밸런스 조정'!$E$3+'밸런스 조정'!$F$3*(D10-1)+'밸런스 조정'!$C$69*MAX(0,D10-3)^2,0) -> 95 | J10: 기본 공격력 증가
B11: 1 | C11: ATT | D11: 9 | E11: 공격력 | F11: ='밸런스 조정'!$C$3+'밸런스 조정'!$D$3*D11 -> 36 | G11: value | H11: Coin | I11: =ROUND('밸런스 조정'!$E$3+'밸런스 조정'!$F$3*(D11-1)+'밸런스 조정'!$C$69*MAX(0,D11-3)^2,0) -> 122 | J11: 기본 공격력 증가
B12: 1 | C12: ATT | D12: 10 | E12: 공격력 | F12: ='밸런스 조정'!$C$3+'밸런스 조정'!$D$3*D12 -> 40 | G12: value | H12: Coin | I12: =ROUND('밸런스 조정'!$E$3+'밸런스 조정'!$F$3*(D12-1)+'밸런스 조정'!$C$69*MAX(0,D12-3)^2,0) -> 153 | J12: 기본 공격력 증가
B13: 1 | C13: ATT | D13: 11 | E13: 공격력 | F13: ='밸런스 조정'!$C$3+'밸런스 조정'!$D$3*D13 -> 44 | G13: value | H13: Coin | I13: =ROUND('밸런스 조정'!$E$3+'밸런스 조정'!$F$3*(D13-1)+'밸런스 조정'!$C$69*MAX(0,D13-3)^2,0) -> 188 | J13: 기본 공격력 증가
B14: 1 | C14: ATT | D14: 12 | E14: 공격력 | F14: ='밸런스 조정'!$C$3+'밸런스 조정'!$D$3*D14 -> 48 | G14: value | H14: Coin | I14: =ROUND('밸런스 조정'!$E$3+'밸런스 조정'!$F$3*(D14-1)+'밸런스 조정'!$C$69*MAX(0,D14-3)^2,0) -> 227 | J14: 기본 공격력 증가
... B62: 1 | C62: ATT | D62: 60 | E62: 공격력 | F62: ='밸런스 조정'!$C$3+'밸런스 조정'!$D$3*D62 -> 240 | G62: value | H62: Coin | I62: =ROUND('밸런스 조정'!$E$3+'밸런스 조정'!$F$3*(D62-1)+'밸런스 조정'!$C$69*MAX(0,D62-3)^2,0) -> 6803 | J62: 기본 공격력 증가
B63: 2 | C63: HP | D63: 1 | E63: 체력 | F63: ='밸런스 조정'!$C$4+'밸런스 조정'!$D$4*D63+'밸런스 조정'!$C$66*D63*(D63-1) -> 20 | G63: value | H63: Coin | I63: =ROUND('밸런스 조정'!$E$4+'밸런스 조정'!$F$4*(D63-1)+'밸런스 조정'!$C$69*MAX(0,D63-3)^2,0) -> 10 | J63: 최대 체력 증가
B64: 2 | C64: HP | D64: 2 | E64: 체력 | F64: ='밸런스 조정'!$C$4+'밸런스 조정'!$D$4*D64+'밸런스 조정'!$C$66*D64*(D64-1) -> 50 | G64: value | H64: Coin | I64: =ROUND('밸런스 조정'!$E$4+'밸런스 조정'!$F$4*(D64-1)+'밸런스 조정'!$C$69*MAX(0,D64-3)^2,0) -> 15 | J64: 최대 체력 증가
B65: 2 | C65: HP | D65: 3 | E65: 체력 | F65: ='밸런스 조정'!$C$4+'밸런스 조정'!$D$4*D65+'밸런스 조정'!$C$66*D65*(D65-1) -> 90 | G65: value | H65: Coin | I65: =ROUND('밸런스 조정'!$E$4+'밸런스 조정'!$F$4*(D65-1)+'밸런스 조정'!$C$69*MAX(0,D65-3)^2,0) -> 20 | J65: 최대 체력 증가
B66: 2 | C66: HP | D66: 4 | E66: 체력 | F66: ='밸런스 조정'!$C$4+'밸런스 조정'!$D$4*D66+'밸런스 조정'!$C$66*D66*(D66-1) -> 140 | G66: value | H66: Coin | I66: =ROUND('밸런스 조정'!$E$4+'밸런스 조정'!$F$4*(D66-1)+'밸런스 조정'!$C$69*MAX(0,D66-3)^2,0) -> 27 | J66: 최대 체력 증가
B67: 2 | C67: HP | D67: 5 | E67: 체력 | F67: ='밸런스 조정'!$C$4+'밸런스 조정'!$D$4*D67+'밸런스 조정'!$C$66*D67*(D67-1) -> 200 | G67: value | H67: Coin | I67: =ROUND('밸런스 조정'!$E$4+'밸런스 조정'!$F$4*(D67-1)+'밸런스 조정'!$C$69*MAX(0,D67-3)^2,0) -> 38 | J67: 최대 체력 증가
B68: 2 | C68: HP | D68: 6 | E68: 체력 | F68: ='밸런스 조정'!$C$4+'밸런스 조정'!$D$4*D68+'밸런스 조정'!$C$66*D68*(D68-1) -> 270 | G68: value | H68: Coin | I68: =ROUND('밸런스 조정'!$E$4+'밸런스 조정'!$F$4*(D68-1)+'밸런스 조정'!$C$69*MAX(0,D68-3)^2,0) -> 53 | J68: 최대 체력 증가
B69: 2 | C69: HP | D69: 7 | E69: 체력 | F69: ='밸런스 조정'!$C$4+'밸런스 조정'!$D$4*D69+'밸런스 조정'!$C$66*D69*(D69-1) -> 350 | G69: value | H69: Coin | I69: =ROUND('밸런스 조정'!$E$4+'밸런스 조정'!$F$4*(D69-1)+'밸런스 조정'!$C$69*MAX(0,D69-3)^2,0) -> 72 | J69: 최대 체력 증가
B70: 2 | C70: HP | D70: 8 | E70: 체력 | F70: ='밸런스 조정'!$C$4+'밸런스 조정'!$D$4*D70+'밸런스 조정'!$C$66*D70*(D70-1) -> 440 | G70: value | H70: Coin | I70: =ROUND('밸런스 조정'!$E$4+'밸런스 조정'!$F$4*(D70-1)+'밸런스 조정'!$C$69*MAX(0,D70-3)^2,0) -> 95 | J70: 최대 체력 증가
B71: 2 | C71: HP | D71: 9 | E71: 체력 | F71: ='밸런스 조정'!$C$4+'밸런스 조정'!$D$4*D71+'밸런스 조정'!$C$66*D71*(D71-1) -> 540 | G71: value | H71: Coin | I71: =ROUND('밸런스 조정'!$E$4+'밸런스 조정'!$F$4*(D71-1)+'밸런스 조정'!$C$69*MAX(0,D71-3)^2,0) -> 122 | J71: 최대 체력 증가
B72: 2 | C72: HP | D72: 10 | E72: 체력 | F72: ='밸런스 조정'!$C$4+'밸런스 조정'!$D$4*D72+'밸런스 조정'!$C$66*D72*(D72-1) -> 650 | G72: value | H72: Coin | I72: =ROUND('밸런스 조정'!$E$4+'밸런스 조정'!$F$4*(D72-1)+'밸런스 조정'!$C$69*MAX(0,D72-3)^2,0) -> 153 | J72: 최대 체력 증가
B73: 2 | C73: HP | D73: 11 | E73: 체력 | F73: ='밸런스 조정'!$C$4+'밸런스 조정'!$D$4*D73+'밸런스 조정'!$C$66*D73*(D73-1) -> 770 | G73: value | H73: Coin | I73: =ROUND('밸런스 조정'!$E$4+'밸런스 조정'!$F$4*(D73-1)+'밸런스 조정'!$C$69*MAX(0,D73-3)^2,0) -> 188 | J73: 최대 체력 증가
B74: 2 | C74: HP | D74: 12 | E74: 체력 | F74: ='밸런스 조정'!$C$4+'밸런스 조정'!$D$4*D74+'밸런스 조정'!$C$66*D74*(D74-1) -> 900 | G74: value | H74: Coin | I74: =ROUND('밸런스 조정'!$E$4+'밸런스 조정'!$F$4*(D74-1)+'밸런스 조정'!$C$69*MAX(0,D74-3)^2,0) -> 227 | J74: 최대 체력 증가
... B122: 2 | C122: HP | D122: 60 | E122: 체력 | F122: ='밸런스 조정'!$C$4+'밸런스 조정'!$D$4*D122+'밸런스 조정'!$C$66*D122*(D122-1) -> 18900 | G122: value | H122: Coin | I122: =ROUND('밸런스 조정'!$E$4+'밸런스 조정'!$F$4*(D122-1)+'밸런스 조정'!$C$69*MAX(0,D122-3)^2,0) -> 6803 | J122: 최대 체력 증가
B123: 3 | C123: ATT_SPEED | D123: 1 | E123: 공속 | F123: ='밸런스 조정'!$C$5+'밸런스 조정'!$D$5*D123 -> 5 | G123: percent | H123: Coin | I123: =ROUND('밸런스 조정'!$E$5+'밸런스 조정'!$F$5*(D123-1),0) -> 45 | J123: 공격 속도 증가
B124: 3 | C124: ATT_SPEED | D124: 2 | E124: 공속 | F124: ='밸런스 조정'!$C$5+'밸런스 조정'!$D$5*D124 -> 10 | G124: percent | H124: Coin | I124: =ROUND('밸런스 조정'!$E$5+'밸런스 조정'!$F$5*(D124-1),0) -> 65 | J124: 공격 속도 증가
B125: 3 | C125: ATT_SPEED | D125: 3 | E125: 공속 | F125: ='밸런스 조정'!$C$5+'밸런스 조정'!$D$5*D125 -> 15 | G125: percent | H125: Coin | I125: =ROUND('밸런스 조정'!$E$5+'밸런스 조정'!$F$5*(D125-1),0) -> 85 | J125: 공격 속도 증가
B126: 3 | C126: ATT_SPEED | D126: 4 | E126: 공속 | F126: ='밸런스 조정'!$C$5+'밸런스 조정'!$D$5*D126 -> 20 | G126: percent | H126: Coin | I126: =ROUND('밸런스 조정'!$E$5+'밸런스 조정'!$F$5*(D126-1),0) -> 105 | J126: 공격 속도 증가
B127: 3 | C127: ATT_SPEED | D127: 5 | E127: 공속 | F127: ='밸런스 조정'!$C$5+'밸런스 조정'!$D$5*D127 -> 25 | G127: percent | H127: Coin | I127: =ROUND('밸런스 조정'!$E$5+'밸런스 조정'!$F$5*(D127-1),0) -> 125 | J127: 공격 속도 증가
B128: 3 | C128: ATT_SPEED | D128: 6 | E128: 공속 | F128: ='밸런스 조정'!$C$5+'밸런스 조정'!$D$5*D128 -> 30 | G128: percent | H128: Coin | I128: =ROUND('밸런스 조정'!$E$5+'밸런스 조정'!$F$5*(D128-1),0) -> 145 | J128: 공격 속도 증가
B129: 3 | C129: ATT_SPEED | D129: 7 | E129: 공속 | F129: ='밸런스 조정'!$C$5+'밸런스 조정'!$D$5*D129 -> 35 | G129: percent | H129: Coin | I129: =ROUND('밸런스 조정'!$E$5+'밸런스 조정'!$F$5*(D129-1),0) -> 165 | J129: 공격 속도 증가
B130: 3 | C130: ATT_SPEED | D130: 8 | E130: 공속 | F130: ='밸런스 조정'!$C$5+'밸런스 조정'!$D$5*D130 -> 40 | G130: percent | H130: Coin | I130: =ROUND('밸런스 조정'!$E$5+'밸런스 조정'!$F$5*(D130-1),0) -> 185 | J130: 공격 속도 증가
B131: 3 | C131: ATT_SPEED | D131: 9 | E131: 공속 | F131: ='밸런스 조정'!$C$5+'밸런스 조정'!$D$5*D131 -> 45 | G131: percent | H131: Coin | I131: =ROUND('밸런스 조정'!$E$5+'밸런스 조정'!$F$5*(D131-1),0) -> 205 | J131: 공격 속도 증가
B132: 3 | C132: ATT_SPEED | D132: 10 | E132: 공속 | F132: ='밸런스 조정'!$C$5+'밸런스 조정'!$D$5*D132 -> 50 | G132: percent | H132: Coin | I132: =ROUND('밸런스 조정'!$E$5+'밸런스 조정'!$F$5*(D132-1),0) -> 225 | J132: 공격 속도 증가
B133: 3 | C133: ATT_SPEED | D133: 11 | E133: 공속 | F133: ='밸런스 조정'!$C$5+'밸런스 조정'!$D$5*D133 -> 55 | G133: percent | H133: Coin | I133: =ROUND('밸런스 조정'!$E$5+'밸런스 조정'!$F$5*(D133-1),0) -> 245 | J133: 공격 속도 증가
B134: 3 | C134: ATT_SPEED | D134: 12 | E134: 공속 | F134: ='밸런스 조정'!$C$5+'밸런스 조정'!$D$5*D134 -> 60 | G134: percent | H134: Coin | I134: =ROUND('밸런스 조정'!$E$5+'밸런스 조정'!$F$5*(D134-1),0) -> 265 | J134: 공격 속도 증가
... B152: 3 | C152: ATT_SPEED | D152: 30 | E152: 공속 | F152: ='밸런스 조정'!$C$5+'밸런스 조정'!$D$5*D152 -> 150 | G152: percent | H152: Coin | I152: =ROUND('밸런스 조정'!$E$5+'밸런스 조정'!$F$5*(D152-1),0) -> 625 | J152: 공격 속도 증가
...

Sheet 스킨
B2: 식별 순서 | C2: 항목(이름) | D2: 가격 타입 | E2: 가격 수치 | F2: 항목 | G2: 보너스 타입 | H2: 보너스 값 타입 | I2: 보너스 수치
B3: 1 | C3: Original | D3: Coin
B4: 2 | C4: Pink | D4: Coin | E4: 5000 | F4: 보스 데미지 | G4: BOSS_DAMAGE | H4: Value | I4: 50
B5: 3 | C5: Zombie | D5: Coin | E5: 5000 | F5: 공격력 | G5: ATT | H5: Value | I5: 30
B6: 4 | C6: Ice | D6: Coin | E6: 5000 | F6: 공속 | G6: ATT_SPEED | H6: Percent | I6: 20
B7: 5 | C7: Wood | D7: Coin | E7: 5000 | F7: 체력 | G7: HP | H7: Value | I7: 50
B8: 6 | C8: Fire | D8: Jewel | E8: 1000 | F8: 보스 데미지 | G8: BOSS_DAMAGE | H8: Percent | I8: 50
B9: 7 | C9: Army | D9: Jewel | E9: 1000 | F9: 공격력 | G9: ATT | H9: Percent | I9: 30
B10: 8 | C10: Cyber | D10: Jewel | E10: 1500 | F10: 체력 회복 | G10: HP_REGEN | H10: Value | I10: 10
B11: 9 | C11: Christmas | D11: Jewel | E11: 1500 | F11: 코인 보너스 | G11: COIN_BONUS | H11: Percent | I11: 100

Sheet 보너스
B2: 식별 순번 | C2: 식별 Enum | D2: 레벨 | E2: 별칭 | F2: 이름 | G2: 항목 | H2: 수치 | I2: 수치 타입 | J2: 가격 타입 | K2: 가격 수치 | L2: 기타 설명 | M2: 최소 | N2: 최대
B3: 1 | C3: Normal | D3: 1 | E3: 날카로운 일격 | F3: 공격력 | G3: att | I3: value | M3: 12 | N3: 18
B4: 2 | C4: Normal | D4: 1 | E4: 전투 본능 | F4: 공격력 | G4: attPercent | I4: percent | M4: 10 | N4: 15
B5: 3 | C5: Normal | D5: 1 | E5: 속사 태세 | F5: 공속 | G5: attackSpeed | I5: percent | M5: 8 | N5: 14
B6: 4 | C6: Normal | D6: 1 | E6: 장거리 탄 | F6: 사거리 | G6: missileDistance | I6: percent | M6: 15 | N6: 23
B7: 5 | C7: Normal | D7: 1 | E7: 든든항 생명 | F7: 체력 | G7: hp | I7: value | L7: 최대 체력과 현재 체력을 함께 증가 | M7: 12 | N7: 20
B8: 6 | C8: Normal | D8: 1 | E8: 생존 본능 | F8: 체력 | G8: hpPercent | I8: percent | L8: 최대 체력과 현재 체력을 함께 증가 | M8: 10 | N8: 17
B9: 7 | C9: Rare | D9: 1 | E9: 지상 지원군 | F9: 퉁퉁퉁 | G9: tungtungAdd | I9: value | M9: 1 | N9: 1
B10: 8 | C10: Rare | D10: 1 | E10: 공중 지원군 | F10: 붐바르 | G10: boombarAdd | I10: value | M10: 1 | N10: 1
B11: 9 | C11: Unique | D11: 1 | E11: 다중 탄막 | F11: 미사일 | G11: missileAdd | I11: value | M11: 1 | N11: 1
B12: 10 | C12: Unique | D12: 1 | E12: 파멸의 일격 | F12: 공격력 | G12: att | I12: value | M12: 36 | N12: 54
B13: 11 | C13: Unique | D13: 1 | E13: 광전사의 힘 | F13: 공격력 | G13: attPercent | I13: percent | M13: =M4*3 -> 30 | N13: =M13*1.5 -> 45
B14: 12 | C14: Unique | D14: 1 | E14: 폭풍 속사 | F14: 공속 | G14: attackSpeed | I14: percent | M14: =M5*3 -> 24 | N14: =M14*1.5 -> 36
B15: 13 | C15: Unique | D15: 1 | E15: 초월 사격 | F15: 사거리 | G15: missileDistance | I15: percent | M15: =M6*3 -> 45 | N15: =ROUND(M15*1.5,0) -> 68
B16: 14 | C16: Unique | D16: 1 | E16: 불굴의 생명 | F16: 체력 | G16: hp | I16: value | L16: 최대 체력과 현재 체력을 함께 증가 | M16: =M7*3 -> 36 | N16: =M16*1.5 -> 54
B17: 15 | C17: Unique | D17: 1 | E17: 철벽의 생존 | F17: 체력 | G17: hpPercent | I17: percent | L17: 최대 체력과 현재 체력을 함께 증가 | M17: =M8*3 -> 30 | N17: =M17*1.5 -> 45

Sheet 몬스터
B2: 순번 | C2: 챕터 | D2: 스테이지 | E2: 티어 | F2: 공격력 | G2: 체력 | H2: 기타 설명
B3: 1 | C3: 1 | D3: 1 | E3: Normal | F3: 33 | G3: 55
B4: 2 | C4: 1 | D4: 1 | E4: Elite | F4: 55 | G4: =G3*2 -> 110
B5: 3 | C5: 1 | D5: 1 | E5: Boss | F5: 165 | G5: =ROUNDUP(G4*1.7,-1) -> 190
B6: 4 | C6: 1 | D6: 2 | E6: Normal | F6: 36 | G6: =G3+5 -> 60
B7: 5 | C7: 1 | D7: 2 | E7: Elite | F7: 60 | G7: =G6*2 -> 120
B8: 6 | C8: 1 | D8: 2 | E8: Boss | F8: 180 | G8: =ROUNDUP(G7*1.7,-1) -> 210
B9: 7 | C9: 1 | D9: 3 | E9: Normal | F9: 39 | G9: =G6+5 -> 65
B10: 8 | C10: 1 | D10: 3 | E10: Elite | F10: 65 | G10: =G9*2 -> 130
B11: 9 | C11: 1 | D11: 3 | E11: Boss | F11: 195 | G11: =ROUNDUP(G10*1.7,-1) -> 230
B12: 10 | C12: 1 | D12: 4 | E12: Normal | F12: 42 | G12: =G9+5 -> 70
B13: 11 | C13: 1 | D13: 4 | E13: Elite | F13: 70 | G13: =G12*2 -> 140
B14: 12 | C14: 1 | D14: 4 | E14: Boss | F14: 210 | G14: =ROUNDUP(G13*1.7,-1) -> 240
B15: 13 | C15: 1 | D15: 5 | E15: Normal | F15: 45 | G15: =G12+5 -> 75
B16: 14 | C16: 1 | D16: 5 | E16: Elite | F16: 75 | G16: =G15*2 -> 150
B17: 15 | C17: 1 | D17: 5 | E17: Boss | F17: 225 | G17: =ROUNDUP(G16*1.7,-1) -> 260
B18: 16 | C18: 1 | D18: 6 | E18: Normal | F18: 48 | G18: =G15+5 -> 80
B19: 17 | C19: 1 | D19: 6 | E19: Elite | F19: 80 | G19: =G18*2 -> 160
B20: 18 | C20: 1 | D20: 6 | E20: Boss | F20: 240 | G20: =ROUNDUP(G19*1.7,-1) -> 280
B21: 19 | C21: 1 | D21: 7 | E21: Normal | F21: 51 | G21: =G18+5 -> 85
B22: 20 | C22: 1 | D22: 7 | E22: Elite | F22: 85 | G22: =G21*2 -> 170
B23: 21 | C23: 1 | D23: 7 | E23: Boss | F23: 255 | G23: =ROUNDUP(G22*1.7,-1) -> 290
B24: 22 | C24: 1 | D24: 8 | E24: Normal | F24: 54 | G24: =G21+5 -> 90
B25: 23 | C25: 1 | D25: 8 | E25: Elite | F25: 90 | G25: =G24*2 -> 180
B26: 24 | C26: 1 | D26: 8 | E26: Boss | F26: 270 | G26: =ROUNDUP(G25*1.7,-1) -> 310
B27: 25 | C27: 1 | D27: 9 | E27: Normal | F27: 57 | G27: =G24+5 -> 95
B28: 26 | C28: 1 | D28: 9 | E28: Elite | F28: 95 | G28: =G27*2 -> 190
B29: 27 | C29: 1 | D29: 9 | E29: Boss | F29: 285 | G29: =ROUNDUP(G28*1.7,-1) -> 330
B30: 28 | C30: 1 | D30: 10 | E30: Normal | F30: 60 | G30: =G27+5 -> 100
B31: 29 | C31: 1 | D31: 10 | E31: Elite | F31: 100 | G31: =G30*2 -> 200
B32: 30 | C32: 1 | D32: 10 | E32: Boss | F32: 300 | G32: =ROUNDUP(G31*1.7,-1) -> 340
B33: 31 | C33: 2 | D33: 1 | E33: Normal | F33: 63 | G33: =G30+5 -> 105
B34: 32 | C34: 2 | D34: 1 | E34: Elite | F34: 105 | G34: =G33*2 -> 210
B35: 33 | C35: 2 | D35: 1 | E35: Boss | F35: 315 | G35: =ROUNDUP(G34*1.7,-1) -> 360
B36: 34 | C36: 2 | D36: 2 | E36: Normal | F36: 66 | G36: =G33+5 -> 110
B37: 35 | C37: 2 | D37: 2 | E37: Elite | F37: 110 | G37: =G36*2 -> 220
B38: 36 | C38: 2 | D38: 2 | E38: Boss | F38: 330 | G38: =ROUNDUP(G37*1.7,-1) -> 380
B39: 37 | C39: 2 | D39: 3 | E39: Normal | F39: 69 | G39: =G36+5 -> 115
B40: 38 | C40: 2 | D40: 3 | E40: Elite | F40: 115 | G40: =G39*2 -> 230
B41: 39 | C41: 2 | D41: 3 | E41: Boss | F41: 345 | G41: =ROUNDUP(G40*1.7,-1) -> 400
...

Sheet 패턴
B2: 순번 | C2: 챕터 | D2: 스테이지 | E2: 1패턴 | F2: 1난이도 | G2: 2패턴 | H2: 2난이도 | I2: 3패턴 | J2: 3난이도 | K2: 4패턴 | L2: 4난이도 | M2: 5패턴 | N2: 5난이도 | O2: 6패턴 | P2: 6난이도 | Q2: 기타설명
B3: 1 | C3: 1 | D3: 1 | E3: Oil | F3: Easy | G3: Hole | H3: Easy | I3: Oil | J3: Easy | Q3: 초반 튜토리얼: Hole/Oil/Bucket 학습
B4: 2 | C4: 1 | D4: 2 | E4: Hole | F4: Easy | G4: Oil | H4: Easy | I4: Hole | J4: Easy | Q4: 초반 튜토리얼: Hole/Oil/Bucket 학습
B5: 3 | C5: 1 | D5: 3 | E5: Oil | F5: Easy | G5: Hole | H5: Easy | I5: Oil | J5: Easy | Q5: 초반 튜토리얼: Hole/Oil/Bucket 학습
B6: 4 | C6: 1 | D6: 4 | E6: Hole | F6: Easy | G6: Oil | H6: Easy | I6: Bucket | J6: Easy | Q6: 초반 튜토리얼: Hole/Oil/Bucket 학습
B7: 5 | C7: 1 | D7: 5 | E7: Oil | F7: Easy | G7: Hole | H7: Easy | I7: Bucket | J7: Easy | Q7: 초반 튜토리얼: Hole/Oil/Bucket 학습
B8: 6 | C8: 1 | D8: 6 | E8: Hole | F8: Easy | G8: Oil | H8: Easy | I8: Bucket | J8: Easy | Q8: 초반 튜토리얼: Hole/Oil/Bucket 학습
B9: 7 | C9: 1 | D9: 7 | E9: Oil | F9: Easy | G9: Hole | H9: Easy | I9: Oil | J9: Easy | K9: Bucket | L9: Easy | Q9: 초반 튜토리얼: Hole/Oil/Bucket 학습
B10: 8 | C10: 1 | D10: 8 | E10: Hole | F10: Easy | G10: Oil | H10: Easy | I10: Hole | J10: Easy | K10: Bucket | L10: Normal | Q10: 초반 튜토리얼: Hole/Oil/Bucket 학습
B11: 9 | C11: 1 | D11: 9 | E11: Oil | F11: Easy | G11: Hole | H11: Easy | I11: Oil | J11: Easy | K11: Bucket | L11: Normal | Q11: 초반 튜토리얼: Hole/Oil/Bucket 학습
B12: 10 | C12: 1 | D12: 10 | E12: Hole | F12: Easy | G12: Oil | H12: Easy | I12: Hole | J12: Easy | K12: Bucket | L12: Normal | Q12: 초반 튜토리얼: Hole/Oil/Bucket 학습
B13: 11 | C13: 2 | D13: 1 | E13: Bucket | F13: Easy | G13: Hole | H13: Easy | I13: Oil | J13: Easy | K13: Bucket | L13: Easy | Q13: Light 도입
B14: 12 | C14: 2 | D14: 2 | E14: Hole | F14: Easy | G14: Oil | H14: Easy | I14: Bucket | J14: Easy | K14: Hole | L14: Easy | Q14: Light 도입
B15: 13 | C15: 2 | D15: 3 | E15: Oil | F15: Easy | G15: Bucket | H15: Easy | I15: Hole | J15: Easy | K15: Oil | L15: Easy | Q15: Light 도입
B16: 14 | C16: 2 | D16: 4 | E16: Bucket | F16: Easy | G16: Hole | H16: Easy | I16: Oil | J16: Easy | K16: Light | L16: Easy | Q16: Light 도입
B17: 15 | C17: 2 | D17: 5 | E17: Hole | F17: Easy | G17: Oil | H17: Easy | I17: Bucket | J17: Easy | K17: Light | L17: Easy | Q17: Light 도입
B18: 16 | C18: 2 | D18: 6 | E18: Oil | F18: Easy | G18: Bucket | H18: Easy | I18: Hole | J18: Easy | K18: Light | L18: Easy | Q18: Light 도입
B19: 17 | C19: 2 | D19: 7 | E19: Bucket | F19: Easy | G19: Hole | H19: Easy | I19: Oil | J19: Easy | K19: Light | L19: Easy | Q19: Light 도입
B20: 18 | C20: 2 | D20: 8 | E20: Hole | F20: Easy | G20: Oil | H20: Easy | I20: Bucket | J20: Easy | K20: Light | L20: Normal | Q20: Light 도입
... B26: 24 | C26: 3 | D26: 4 | E26: Hole | F26: Easy | G26: Bucket | H26: Easy | I26: Hole | J26: Easy | K26: Seagull | L26: Easy | Q26: Seagull 입문
B27: 25 | C27: 3 | D27: 5 | E27: Oil | F27: Easy | G27: Light | H27: Easy | I27: Oil | J27: Easy | K27: Light | L27: Easy | M27: Oil | N27: Easy | Q27: Seagull 입문
B28: 26 | C28: 3 | D28: 6 | E28: Bucket | F28: Easy | G28: Seagull | H28: Easy | I28: Bucket | J28: Easy | K28: Hole | L28: Normal | M28: Seagull | N28: Easy | Q28: Seagull 입문
B29: 27 | C29: 3 | D29: 7 | E29: Light | F29: Easy | G29: Oil | H29: Easy | I29: Light | J29: Easy | K29: Oil | L29: Normal | M29: Light | N29: Normal | Q29: Seagull 입문
B30: 28 | C30: 3 | D30: 8 | E30: Hole | F30: Easy | G30: Bucket | H30: Easy | I30: Hole | J30: Easy | K30: Bucket | L30: Normal | M30: Seagull | N30: Normal | Q30: Seagull 입문
B31: 29 | C31: 3 | D31: 9 | E31: Oil | F31: Easy | G31: Seagull | H31: Normal | I31: Oil | J31: Easy | K31: Light | L31: Normal | M31: Oil | N31: Normal | Q31: Seagull 입문
B32: 30 | C32: 3 | D32: 10 | E32: Bucket | F32: Easy | G32: Hole | H32: Easy | I32: Bucket | J32: Easy | K32: Hole | L32: Normal | M32: Seagull | N32: Normal | Q32: Seagull 입문
B33: 31 | C33: 4 | D33: 1 | E33: Light | F33: Easy | G33: Hole | H33: Easy | I33: Light | J33: Easy | K33: Hole | L33: Easy | M33: Light | N33: Easy | Q33: Ship 입문
B34: 32 | C34: 4 | D34: 2 | E34: Seagull | F34: Easy | G34: Bucket | H34: Easy | I34: Seagull | J34: Easy | K34: Bucket | L34: Easy | M34: Ship | N34: Easy | Q34: Ship 입문
B35: 33 | C35: 4 | D35: 3 | E35: Hole | F35: Easy | G35: Ship | H35: Easy | I35: Hole | J35: Easy | K35: Light | L35: Easy | M35: Hole | N35: Easy | Q35: Ship 입문
B36: 34 | C36: 4 | D36: 4 | E36: Bucket | F36: Easy | G36: Seagull | H36: Easy | I36: Bucket | J36: Easy | K36: Seagull | L36: Easy | M36: Ship | N36: Easy | Q36: Ship 입문
B37: 35 | C37: 4 | D37: 5 | E37: Light | F37: Easy | G37: Hole | H37: Easy | I37: Light | J37: Easy | K37: Hole | L37: Easy | M37: Light | N37: Normal | Q37: Ship 입문
B38: 36 | C38: 4 | D38: 6 | E38: Seagull | F38: Easy | G38: Ship | H38: Easy | I38: Seagull | J38: Easy | K38: Bucket | L38: Easy | M38: Ship | N38: Easy | Q38: Ship 입문
... B42: 40 | C42: 4 | D42: 10 | E42: Seagull | F42: Easy | G42: Bucket | H42: Easy | I42: Seagull | J42: Easy | K42: Bucket | L42: Easy | M42: Ship | N42: Normal | Q42: Ship 입문
B43: 41 | C43: 5 | D43: 1 | E43: Ship | F43: Easy | G43: Bucket | H43: Easy | I43: Seagull | J43: Easy | K43: Dolphin | L43: Normal | Q43: 5챕터: Dolphin 입문, 해상 적응
B44: 42 | C44: 5 | D44: 2 | E44: Oil | F44: Easy | G44: Light | H44: Easy | I44: Ship | J44: Normal | K44: Dolphin | L44: Normal | Q44: 5챕터: Dolphin 입문, 해상 적응
B45: 43 | C45: 5 | D45: 3 | E45: Bucket | F45: Easy | G45: Seagull | H45: Easy | I45: Oil | J45: Easy | K45: Dolphin | L45: Normal | Q45: 5챕터: Dolphin 입문, 해상 적응
B46: 44 | C46: 5 | D46: 4 | E46: Light | F46: Easy | G46: Ship | H46: Normal | I46: Bucket | J46: Easy | K46: Dolphin | L46: Normal | Q46: 5챕터: Dolphin 입문, 해상 적응
B47: 45 | C47: 5 | D47: 5 | E47: Seagull | F47: Easy | G47: Oil | H47: Easy | I47: Light | J47: Easy | K47: Ship | L47: Normal | M47: Dolphin | N47: Normal | Q47: 5챕터: Dolphin 입문, 해상 적응
B48: 46 | C48: 5 | D48: 6 | E48: Ship | F48: Normal | G48: Bucket | H48: Normal | I48: Seagull | J48: Normal | K48: Light | L48: Normal | M48: Dolphin | N48: Normal | Q48: 5챕터: Dolphin 입문, 해상 적응
B49: 47 | C49: 5 | D49: 7 | E49: Oil | F49: Easy | G49: Ship | H49: Normal | I49: Light | J49: Normal | K49: Bucket | L49: Normal | M49: Dolphin | N49: Normal | Q49: 5챕터: Dolphin 입문, 해상 적응
...

Sheet 패턴목록
A1: Pattern | B1: Difficulty
A2: None | B2: Easy
A3: Hole | B3: Normal
A4: Oil | B4: Hard
A5: Ship
A6: Light
A7: Oldman
A8: Dolphin
A9: Bucket
A10: Seagull

Sheet 환경 변수
B2: 변수명 | C2: 변수 타입 | D2: 값1 | E2: 값2 | F2: 값3
B3: playerSpeed | C3: float | D3: 8
B4: playerDefaultAtt | C4: float | D4: 8
B5: playerDefaultHp | C5: float | D5: 60
B6: misspleSpeed | C6: float | D6: 32
B7: missileDuration | C7: float | D7: 1.25 | G7: =D6*D7 -> 40
B8: playerDefaultFireRate | C8: float | D8: 1.6
B9: playerDefaultMissileCount | C9: float | D9: 1
B10: playerSpeed_Noryangjin_MapTool_Mode_SR18 | C10: float | D10: ='밸런스 조정'!C59 -> 8.84
B11: playerSpeed_HighWay | C11: float | D11: ='밸런스 조정'!C60 -> 7.8
B12: playerSpeed_RestStop | C12: float | D12: ='밸런스 조정'!C88 -> 7.8
B13: progressRewardInterval | C13: float | D13: ='밸런스 조정'!C95 -> 15
B14: progressCoinPerCheckpoint_HighWay | C14: float | D14: ='밸런스 조정'!C96 -> 62
B15: progressCoinPerCheckpoint_RestStop | C15: float | D15: ='밸런스 조정'!C97 -> 350
B16: progressRewardMaximum | C16: float | D16: ='밸런스 조정'!C98 -> 20
B17: progressCoinPerCheckpoint_Noryangjin_MapTool_Mode_SR18 | C17: float | D17: ='밸런스 조정'!C99 -> 0
B18: firstClearJewels_Noryangjin_MapTool_Mode_SR18 | C18: float | D18: ='밸런스 조정'!C100 -> 20
B19: replayClearJewels_Noryangjin_MapTool_Mode_SR18 | C19: float | D19: ='밸런스 조정'!C101 -> 5
B20: firstClearJewels_HighWay | C20: float | D20: ='밸런스 조정'!C102 -> 25
B21: replayClearJewels_HighWay | C21: float | D21: ='밸런스 조정'!C103 -> 5
B22: firstClearJewels_RestStop | C22: float | D22: ='밸런스 조정'!C104 -> 30
B23: replayClearJewels_RestStop | C23: float | D23: ='밸런스 조정'!C105 -> 5
B24: coinPickupRadius_HighWay | C24: float | D24: 3.5
B25: coinPickupRadius_RestStop | C25: float | D25: 3.5
B26: highwayOncomingWarning | C26: float | D26: ='밸런스 조정'!C110 -> 2.2
B27: highwayOncomingSpeed | C27: float | D27: ='밸런스 조정'!C111 -> 16
B28: highwayOncomingDamage | C28: float | D28: ='밸런스 조정'!C112 -> 220
B29: highwayBypassHeal | C29: float | D29: ='밸런스 조정'!C113 -> 0.1
B30: reststopHoldoutSeconds | C30: float | D30: ='밸런스 조정'!C114 -> 30
B31: reststopPoliceHealth | C31: float | D31: ='밸런스 조정'!C115 -> 520
B32: reststopPoliceSpeed | C32: float | D32: ='밸런스 조정'!C116 -> 3.2
B33: reststopPoliceInterval | C33: float | D33: ='밸런스 조정'!C117 -> 1.05
B34: reststopHoldoutHeal | C34: float | D34: ='밸런스 조정'!C118 -> 0.12
B35: hwy2_length | C35: float | D35: ='밸런스 조정'!C119 -> 2340 | E35: 0 | F35: 0
B36: hwy2_runSpeed | C36: float | D36: ='밸런스 조정'!C120 -> 7.8 | E36: 0 | F36: 0
B37: hwy2_laneWidth | C37: float | D37: ='밸런스 조정'!C121 -> 4.4 | E37: 0 | F37: 0
B38: hwy2_sharkScale | C38: float | D38: ='밸런스 조정'!C122 -> 0.8 | E38: 0 | F38: 0
B39: hwy2_cameraScale | C39: float | D39: ='밸런스 조정'!C123 -> 1.15 | E39: 0 | F39: 0
B40: hwy2_medianWidth | C40: float | D40: ='밸런스 조정'!C124 -> 0.84 | E40: 0 | F40: 0
B41: hwy2_medianHeight | C41: float | D41: ='밸런스 조정'!C125 -> 1 | E41: 0 | F41: 0
...

Sheet 몬스터 성장
B2: 챕터 | C2: 티어 | D2: 초기 공격력 | E2: 최종 공격력 | F2: 초기 체력 | G2: 최종 체력 | H2: 계수
B3: 1 | C3: Normal | D3: =VLOOKUP($C3,$K$5:$O$7,2,FALSE)*$H3 -> 33 | E3: =VLOOKUP($C3,$K$5:$O$7,3,FALSE)*$H3 -> 330 | F3: =VLOOKUP($C3,$K$5:$O$7,4,FALSE)*$H3 -> 55 | G3: =VLOOKUP($C3,$K$5:$O$7,5,FALSE)*$H3 -> 550 | H3: 1
B4: 1 | C4: Elite | D4: =VLOOKUP($C4,$K$5:$O$7,2,FALSE)*$H4 -> 55 | E4: =VLOOKUP($C4,$K$5:$O$7,3,FALSE)*$H4 -> 550 | F4: =VLOOKUP($C4,$K$5:$O$7,4,FALSE)*$H4 -> 110 | G4: =VLOOKUP($C4,$K$5:$O$7,5,FALSE)*$H4 -> 1100 | H4: 1 | K4: 참고용 | L4: 초기 공격력 | M4: 최종 공격력 | N4: 초기 체력 | O4: 최종 체력
B5: 1 | C5: Boss | D5: =VLOOKUP($C5,$K$5:$O$7,2,FALSE)*$H5 -> 165 | E5: =VLOOKUP($C5,$K$5:$O$7,3,FALSE)*$H5 -> 1650 | F5: =VLOOKUP($C5,$K$5:$O$7,4,FALSE)*$H5 -> 190 | G5: =VLOOKUP($C5,$K$5:$O$7,5,FALSE)*$H5 -> 1870 | H5: 1 | K5: Normal | L5: 33 | M5: 330 | N5: 55 | O5: 550
B6: 2 | C6: Normal | D6: =VLOOKUP($C6,$K$5:$O$7,2,FALSE)*$H6 -> 66 | E6: =VLOOKUP($C6,$K$5:$O$7,3,FALSE)*$H6 -> 660 | F6: =VLOOKUP($C6,$K$5:$O$7,4,FALSE)*$H6 -> 110 | G6: =VLOOKUP($C6,$K$5:$O$7,5,FALSE)*$H6 -> 1100 | H6: 2 | K6: Elite | L6: 55 | M6: 550 | N6: 110 | O6: 1100
B7: 2 | C7: Elite | D7: =VLOOKUP($C7,$K$5:$O$7,2,FALSE)*$H7 -> 110 | E7: =VLOOKUP($C7,$K$5:$O$7,3,FALSE)*$H7 -> 1100 | F7: =VLOOKUP($C7,$K$5:$O$7,4,FALSE)*$H7 -> 220 | G7: =VLOOKUP($C7,$K$5:$O$7,5,FALSE)*$H7 -> 2200 | H7: 2 | K7: Boss | L7: 165 | M7: 1650 | N7: 190 | O7: 1870
B8: 2 | C8: Boss | D8: =VLOOKUP($C8,$K$5:$O$7,2,FALSE)*$H8 -> 330 | E8: =VLOOKUP($C8,$K$5:$O$7,3,FALSE)*$H8 -> 3300 | F8: =VLOOKUP($C8,$K$5:$O$7,4,FALSE)*$H8 -> 380 | G8: =VLOOKUP($C8,$K$5:$O$7,5,FALSE)*$H8 -> 3740 | H8: 2
B9: 3 | C9: Normal | D9: =VLOOKUP($C9,$K$5:$O$7,2,FALSE)*$H9 -> 99 | E9: =VLOOKUP($C9,$K$5:$O$7,3,FALSE)*$H9 -> 990 | F9: =VLOOKUP($C9,$K$5:$O$7,4,FALSE)*$H9 -> 165 | G9: =VLOOKUP($C9,$K$5:$O$7,5,FALSE)*$H9 -> 1650 | H9: 3
B10: 3 | C10: Elite | D10: =VLOOKUP($C10,$K$5:$O$7,2,FALSE)*$H10 -> 165 | E10: =VLOOKUP($C10,$K$5:$O$7,3,FALSE)*$H10 -> 1650 | F10: =VLOOKUP($C10,$K$5:$O$7,4,FALSE)*$H10 -> 330 | G10: =VLOOKUP($C10,$K$5:$O$7,5,FALSE)*$H10 -> 3300 | H10: 3
B11: 3 | C11: Boss | D11: =VLOOKUP($C11,$K$5:$O$7,2,FALSE)*$H11 -> 495 | E11: =VLOOKUP($C11,$K$5:$O$7,3,FALSE)*$H11 -> 4950 | F11: =VLOOKUP($C11,$K$5:$O$7,4,FALSE)*$H11 -> 570 | G11: =VLOOKUP($C11,$K$5:$O$7,5,FALSE)*$H11 -> 5610 | H11: 3
B12: 4 | C12: Normal | D12: =VLOOKUP($C12,$K$5:$O$7,2,FALSE)*$H12 -> 132 | E12: =VLOOKUP($C12,$K$5:$O$7,3,FALSE)*$H12 -> 1320 | F12: =VLOOKUP($C12,$K$5:$O$7,4,FALSE)*$H12 -> 220 | G12: =VLOOKUP($C12,$K$5:$O$7,5,FALSE)*$H12 -> 2200 | H12: 4
B13: 4 | C13: Elite | D13: =VLOOKUP($C13,$K$5:$O$7,2,FALSE)*$H13 -> 220 | E13: =VLOOKUP($C13,$K$5:$O$7,3,FALSE)*$H13 -> 2200 | F13: =VLOOKUP($C13,$K$5:$O$7,4,FALSE)*$H13 -> 440 | G13: =VLOOKUP($C13,$K$5:$O$7,5,FALSE)*$H13 -> 4400 | H13: 4
B14: 4 | C14: Boss | D14: =VLOOKUP($C14,$K$5:$O$7,2,FALSE)*$H14 -> 660 | E14: =VLOOKUP($C14,$K$5:$O$7,3,FALSE)*$H14 -> 6600 | F14: =VLOOKUP($C14,$K$5:$O$7,4,FALSE)*$H14 -> 760 | G14: =VLOOKUP($C14,$K$5:$O$7,5,FALSE)*$H14 -> 7480 | H14: 4
B15: 5 | C15: Normal | D15: =VLOOKUP($C15,$K$5:$O$7,2,FALSE)*$H15 -> 165 | E15: =VLOOKUP($C15,$K$5:$O$7,3,FALSE)*$H15 -> 1650 | F15: =VLOOKUP($C15,$K$5:$O$7,4,FALSE)*$H15 -> 275 | G15: =VLOOKUP($C15,$K$5:$O$7,5,FALSE)*$H15 -> 2750 | H15: 5
B16: 5 | C16: Elite | D16: =VLOOKUP($C16,$K$5:$O$7,2,FALSE)*$H16 -> 275 | E16: =VLOOKUP($C16,$K$5:$O$7,3,FALSE)*$H16 -> 2750 | F16: =VLOOKUP($C16,$K$5:$O$7,4,FALSE)*$H16 -> 550 | G16: =VLOOKUP($C16,$K$5:$O$7,5,FALSE)*$H16 -> 5500 | H16: 5
B17: 5 | C17: Boss | D17: =VLOOKUP($C17,$K$5:$O$7,2,FALSE)*$H17 -> 825 | E17: =VLOOKUP($C17,$K$5:$O$7,3,FALSE)*$H17 -> 8250 | F17: =VLOOKUP($C17,$K$5:$O$7,4,FALSE)*$H17 -> 950 | G17: =VLOOKUP($C17,$K$5:$O$7,5,FALSE)*$H17 -> 9350 | H17: 5

Sheet 적 배치
B1: 보너스 선택25 : 적50 : 기믹25. 공격력·체력·드롭·코인보상은 이 표가 최종 기준입니다.
B2: 순번 | C2: 맵 | D2: 배치ID | E2: 사용 | F2: 이벤트 | G2: 이동속도 | H2: 이동거리 | I2: 발동앞거리 | J2: 발사준비초 | K2: 투사체속도 | L2: 설명 | M2: 타입 | N2: 공격력 | O2: 체력 | P2: 체력증가율 | Q2: 보너스드롭 | R2: 코인보상 | S2: 차종 | T2: 차량경로 | U2: 차량거리 | V2: 차로번호 | W2: 등장거리 | X2: 사건ID | Y2: 사고앞줄
B3: 1 | C3: Noryangjin_MapTool_Mode_SR18 | D3: SR18_L_E01_T005_Enemy_OldMan | E3: 1 | F3: 이동 후 공격 | G3: 1.8 | H3: 2 | I3: 12 | J3: 2 | K3: 12 | L3: 공격력·체력은 밸런스 조정 시트에서 계산. | M3: Normal | N3: ='밸런스 조정'!$C$15 -> 8 | O3: ='밸런스 조정'!$C$16 -> 45 | P3: ='밸런스 조정'!$C$18 -> 0.16 | Q3: ='밸런스 조정'!$C$64 -> 0 | R3: ='밸런스 조정'!$C$65*IF(M3="Boss",5,IF(M3="Elite",2,1)) -> 10
B4: 2 | C4: Noryangjin_MapTool_Mode_SR18 | D4: SR18_L_E01_T005_Enemy_OldMan_Right | E4: 1 | F4: 공격 한 번 | G4: 2 | H4: 0 | I4: 5 | J4: 2 | K4: 12 | L4: 왼쪽 적보다 체력 15% 증가. 접근 시차를 두고 발동. | M4: Normal | N4: =N3 -> 8 | O4: =ROUND(O3*(1+P4),0) -> 52 | P4: 0.15 | Q4: ='밸런스 조정'!$C$64 -> 0 | R4: ='밸런스 조정'!$C$65*IF(M4="Boss",5,IF(M4="Elite",2,1)) -> 10
B5: 3 | C5: Noryangjin_MapTool_Mode_SR18 | D5: SR18_L_E02_T017_Enemy_OldMan | E5: 1 | F5: 공격 반복 | G5: 2 | H5: 0 | I5: 8 | J5: 2 | K5: 12 | L5: 공격력·체력은 밸런스 조정 시트에서 계산. | M5: Normal | N5: =ROUND(N3*(1+'밸런스 조정'!$C$17),0) -> 8 | O5: ='밸런스 조정'!$C$23 -> 55 | P5: ='밸런스 조정'!$C$18 -> 0.16 | Q5: ='밸런스 조정'!$C$64 -> 0 | R5: ='밸런스 조정'!$C$65*IF(M5="Boss",5,IF(M5="Elite",2,1)) -> 10
B6: 4 | C6: Noryangjin_MapTool_Mode_SR18 | D6: SR18_L_E02_T017_Enemy_OldMan_Right | E6: 1 | F6: 공격 반복 | G6: 2 | H6: 0 | I6: 5 | J6: 2 | K6: 12 | L6: 왼쪽 적보다 체력 15% 증가. 접근 시차를 두고 발동. | M6: Normal | N6: =N5 -> 8 | O6: =ROUND(O5*(1+P6),0) -> 63 | P6: 0.15 | Q6: ='밸런스 조정'!$C$64 -> 0 | R6: ='밸런스 조정'!$C$65*IF(M6="Boss",5,IF(M6="Elite",2,1)) -> 10
B7: 5 | C7: Noryangjin_MapTool_Mode_SR18 | D7: SR18_L_E03_T029_Enemy_YllowMan_Sword | E7: 1 | F7: 왕복 | G7: 2.5 | H7: 8 | I7: 18 | J7: 2 | K7: 12 | L7: 공격력·체력은 밸런스 조정 시트에서 계산. | M7: Normal | N7: =ROUND(N5*(1+'밸런스 조정'!$C$17),0) -> 8 | O7: ='밸런스 조정'!$C$24 -> 130 | P7: ='밸런스 조정'!$C$18 -> 0.16 | Q7: ='밸런스 조정'!$C$64 -> 0 | R7: ='밸런스 조정'!$C$65*IF(M7="Boss",5,IF(M7="Elite",2,1)) -> 10
B8: 6 | C8: Noryangjin_MapTool_Mode_SR18 | D8: SR18_L_E03_T029_Enemy_YllowMan_Sword_Right | E8: 1 | F8: 왕복 | G8: 2.5 | H8: 8 | I8: 14 | J8: 2 | K8: 12 | L8: 왼쪽 적보다 체력 15% 증가. 접근 시차를 두고 발동. | M8: Normal | N8: =N7 -> 8 | O8: =ROUND(O7*(1+P8),0) -> 150 | P8: 0.15 | Q8: ='밸런스 조정'!$C$64 -> 0 | R8: ='밸런스 조정'!$C$65*IF(M8="Boss",5,IF(M8="Elite",2,1)) -> 10
B9: 7 | C9: Noryangjin_MapTool_Mode_SR18 | D9: SR18_L_E04_T041_Enemy_OldMan | E9: 1 | F9: 공격 반복 | G9: 2 | H9: 0 | I9: 8 | J9: 2 | K9: 12 | L9: 공격력·체력은 밸런스 조정 시트에서 계산. | M9: Normal | N9: =ROUND(N7*(1+'밸런스 조정'!$C$17),0) -> 8 | O9: =ROUND(O7*(1+P9),0) -> 151 | P9: ='밸런스 조정'!$C$18 -> 0.16 | Q9: ='밸런스 조정'!$C$64 -> 0 | R9: ='밸런스 조정'!$C$65*IF(M9="Boss",5,IF(M9="Elite",2,1)) -> 10
B10: 8 | C10: Noryangjin_MapTool_Mode_SR18 | D10: SR18_L_E04_T041_Enemy_OldMan_Right | E10: 1 | F10: 공격 반복 | G10: 2 | H10: 0 | I10: 5 | J10: 2 | K10: 12 | L10: 왼쪽 적보다 체력 15% 증가. 접근 시차를 두고 발동. | M10: Normal | N10: =N9 -> 8 | O10: =ROUND(O9*(1+P10),0) -> 174 | P10: 0.15 | Q10: ='밸런스 조정'!$C$64 -> 0 | R10: ='밸런스 조정'!$C$65*IF(M10="Boss",5,IF(M10="Elite",2,1)) -> 10
B11: 9 | C11: Noryangjin_MapTool_Mode_SR18 | D11: SR18_L_E05_T053_Enemy_Guard | E11: 1 | F11: 전방 매복 사격 | G11: 3 | H11: 4 | I11: 36 | J11: 0.45 | K11: 11.9 | L11: 공격력·체력은 밸런스 조정 시트에서 계산. | M11: Normal | N11: =(ROUND(N9*(1+'밸런스 조정'!$C$17),0))*0.45 -> 3.6 | O11: =ROUND(O9*(1+P11),0) -> 175 | P11: ='밸런스 조정'!$C$18 -> 0.16 | Q11: ='밸런스 조정'!$C$64 -> 0 | R11: ='밸런스 조정'!$C$65*IF(M11="Boss",5,IF(M11="Elite",2,1)) -> 10
B12: 10 | C12: Noryangjin_MapTool_Mode_SR18 | D12: SR18_L_E05_T053_Enemy_Guard_Right | E12: 1 | F12: 전방 매복 사격 | G12: 3 | H12: 4 | I12: 36 | J12: 0.45 | K12: 11.9 | L12: 왼쪽 적보다 체력 15% 증가. 접근 시차를 두고 발동. | M12: Normal | N12: =N11 -> 3.6 | O12: =ROUND(O11*(1+P12),0) -> 201 | P12: 0.15 | Q12: ='밸런스 조정'!$C$64 -> 0 | R12: ='밸런스 조정'!$C$65*IF(M12="Boss",5,IF(M12="Elite",2,1)) -> 10
B13: 11 | C13: Noryangjin_MapTool_Mode_SR18 | D13: SR18_L_E06_T065_Enemy_YllowMan_Net | E13: 0 | F13: 공격 반복 | G13: 2 | H13: 0 | I13: 8 | J13: 2 | K13: 12 | L13: 공격력·체력은 밸런스 조정 시트에서 계산. | M13: Normal | N13: =ROUND(N11*(1+'밸런스 조정'!$C$17),0) -> 4 | O13: =ROUND(O11*(1+P13),0) -> 203 | P13: ='밸런스 조정'!$C$18 -> 0.16 | Q13: ='밸런스 조정'!$C$64 -> 0 | R13: ='밸런스 조정'!$C$65*IF(M13="Boss",5,IF(M13="Elite",2,1)) -> 10
B14: 12 | C14: Noryangjin_MapTool_Mode_SR18 | D14: SR18_L_E06_T065_Enemy_YllowMan_Net_Right | E14: 1 | F14: 공격 반복 | G14: 2 | H14: 0 | I14: 5 | J14: 2 | K14: 12 | L14: 왼쪽 적보다 체력 15% 증가. 접근 시차를 두고 발동. | M14: Boss | N14: =N13 -> 4 | O14: =ROUND(O13*3,0) -> 609 | P14: 0.15 | Q14: ='밸런스 조정'!$C$64 -> 0 | R14: ='밸런스 조정'!$C$65*IF(M14="Boss",5,IF(M14="Elite",2,1)) -> 50
B15: 13 | C15: Noryangjin_MapTool_Mode_SR18 | D15: SR18_L_E07_T077_Enemy_YllowMan_Sword | E15: 1 | F15: 왕복 | G15: 2.5 | H15: 8 | I15: 18 | J15: 2 | K15: 12 | L15: 공격력·체력은 밸런스 조정 시트에서 계산. | M15: Normal | N15: =ROUND(N13*(1+'밸런스 조정'!$C$17),0) -> 4 | O15: =ROUND(O13*(1+P15),0) -> 235 | P15: ='밸런스 조정'!$C$18 -> 0.16 | Q15: ='밸런스 조정'!$C$64 -> 0 | R15: ='밸런스 조정'!$C$65*IF(M15="Boss",5,IF(M15="Elite",2,1)) -> 10
B16: 14 | C16: Noryangjin_MapTool_Mode_SR18 | D16: SR18_L_E07_T077_Enemy_YllowMan_Sword_Right | E16: 1 | F16: 왕복 | G16: 2.5 | H16: 8 | I16: 14 | J16: 2 | K16: 12 | L16: 왼쪽 적보다 체력 15% 증가. 접근 시차를 두고 발동. | M16: Normal | N16: =N15 -> 4 | O16: =ROUND(O15*(1+P16),0) -> 270 | P16: 0.15 | Q16: ='밸런스 조정'!$C$64 -> 0 | R16: ='밸런스 조정'!$C$65*IF(M16="Boss",5,IF(M16="Elite",2,1)) -> 10
B17: 15 | C17: Noryangjin_MapTool_Mode_SR18 | D17: SR18_L_E08_T089_Enemy_FatMan | E17: 1 | F17: 사격 | G17: 0 | H17: 0 | I17: 20 | J17: 0.62 | K17: 18 | L17: 공격력·체력은 밸런스 조정 시트에서 계산. | M17: Elite | N17: 100 | O17: =ROUND(O15*'밸런스 조정'!$C$20,0) -> 423 | Q17: ='밸런스 조정'!$C$64 -> 0 | R17: ='밸런스 조정'!$C$65*IF(M17="Boss",5,IF(M17="Elite",2,1)) -> 20
B18: 16 | C18: Noryangjin_MapTool_Mode_SR18 | D18: SR18_L_E08_T089_Enemy_FatMan_Right | E18: 1 | F18: 사격 | G18: 0 | H18: 0 | I18: 20 | J18: 0.62 | K18: 18 | L18: 왼쪽 적보다 체력 15% 증가. 접근 시차를 두고 발동. | M18: Elite | N18: 100 | O18: =ROUND(O17*(1+P18),0) -> 486 | P18: 0.15 | Q18: ='밸런스 조정'!$C$64 -> 0 | R18: ='밸런스 조정'!$C$65*IF(M18="Boss",5,IF(M18="Elite",2,1)) -> 20
B19: 17 | C19: Noryangjin_MapTool_Mode_SR18 | D19: SR18_L_E09_T101_Enemy_YllowMan_Net | E19: 1 | F19: 공격 반복 | G19: 2 | H19: 0 | I19: 8 | J19: 2 | K19: 12 | L19: 공격력·체력은 밸런스 조정 시트에서 계산. | M19: Normal | N19: =ROUND(N15*(1+'밸런스 조정'!$C$17),0) -> 4 | O19: =ROUND(O15*(1+P19),0) -> 273 | P19: ='밸런스 조정'!$C$18 -> 0.16 | Q19: ='밸런스 조정'!$C$64 -> 0 | R19: ='밸런스 조정'!$C$65*IF(M19="Boss",5,IF(M19="Elite",2,1)) -> 10
B20: 18 | C20: Noryangjin_MapTool_Mode_SR18 | D20: SR18_L_E09_T101_Enemy_YllowMan_Net_Right | E20: 1 | F20: 공격 반복 | G20: 2 | H20: 0 | I20: 5 | J20: 2 | K20: 12 | L20: 왼쪽 적보다 체력 15% 증가. 접근 시차를 두고 발동. | M20: Normal | N20: =N19 -> 4 | O20: =ROUND(O19*(1+P20),0) -> 314 | P20: 0.15 | Q20: ='밸런스 조정'!$C$64 -> 0 | R20: ='밸런스 조정'!$C$65*IF(M20="Boss",5,IF(M20="Elite",2,1)) -> 10
B21: 19 | C21: Noryangjin_MapTool_Mode_SR18 | D21: SR18_L_E10_T113_Enemy_YllowMan_Sword | E21: 1 | F21: 왕복 | G21: 1.4 | H21: 2 | I21: 18 | J21: 2 | K21: 12 | L21: 공격력·체력은 밸런스 조정 시트에서 계산. | M21: Normal | N21: =ROUND(N19*(1+'밸런스 조정'!$C$17),0) -> 4 | O21: =ROUND(O19*(1+P21),0) -> 317 | P21: ='밸런스 조정'!$C$18 -> 0.16 | Q21: ='밸런스 조정'!$C$64 -> 0 | R21: ='밸런스 조정'!$C$65*IF(M21="Boss",5,IF(M21="Elite",2,1)) -> 10
B22: 20 | C22: Noryangjin_MapTool_Mode_SR18 | D22: SR18_L_E10_T113_Enemy_YllowMan_Sword_Right | E22: 1 | F22: 왕복 | G22: 1.4 | H22: 2 | I22: 14 | J22: 2 | K22: 12 | L22: 왼쪽 적보다 체력 15% 증가. 접근 시차를 두고 발동. | M22: Normal | N22: =N21 -> 4 | O22: =ROUND(O21*(1+P22),0) -> 365 | P22: 0.15 | Q22: ='밸런스 조정'!$C$64 -> 0 | R22: ='밸런스 조정'!$C$65*IF(M22="Boss",5,IF(M22="Elite",2,1)) -> 10
B23: 21 | C23: Noryangjin_MapTool_Mode_SR18 | D23: SR18_L_E11_T125_Enemy_OldMan | E23: 1 | F23: 공격 반복 | G23: 2 | H23: 0 | I23: 8 | J23: 2 | K23: 12 | L23: 공격력·체력은 밸런스 조정 시트에서 계산. | M23: Normal | N23: =ROUND(N21*(1+'밸런스 조정'!$C$17),0) -> 4 | O23: =ROUND(O21*(1+P23),0) -> 368 | P23: ='밸런스 조정'!$C$18 -> 0.16 | Q23: ='밸런스 조정'!$C$64 -> 0 | R23: ='밸런스 조정'!$C$65*IF(M23="Boss",5,IF(M23="Elite",2,1)) -> 10
B24: 22 | C24: Noryangjin_MapTool_Mode_SR18 | D24: SR18_L_E11_T125_Enemy_OldMan_Right | E24: 1 | F24: 공격 반복 | G24: 2 | H24: 0 | I24: 5 | J24: 2 | K24: 12 | L24: 왼쪽 적보다 체력 15% 증가. 접근 시차를 두고 발동. | M24: Normal | N24: =N23 -> 4 | O24: =ROUND(O23*(1+P24),0) -> 423 | P24: 0.15 | Q24: ='밸런스 조정'!$C$64 -> 0 | R24: ='밸런스 조정'!$C$65*IF(M24="Boss",5,IF(M24="Elite",2,1)) -> 10
B25: 23 | C25: Noryangjin_MapTool_Mode_SR18 | D25: SR18_L_E12_T137_Enemy_FatMan | E25: 1 | F25: 사격 | G25: 0 | H25: 0 | I25: 16 | J25: 0.62 | K25: 18 | L25: 공격력·체력은 밸런스 조정 시트에서 계산. | M25: Elite | N25: 100 | O25: =ROUND(O23*'밸런스 조정'!$C$20,0) -> 662 | Q25: ='밸런스 조정'!$C$64 -> 0 | R25: ='밸런스 조정'!$C$65*IF(M25="Boss",5,IF(M25="Elite",2,1)) -> 20
B26: 24 | C26: Noryangjin_MapTool_Mode_SR18 | D26: SR18_L_E12_T137_Enemy_FatMan_Right | E26: 1 | F26: 사격 | G26: 0 | H26: 0 | I26: 16 | J26: 0.62 | K26: 18 | L26: 왼쪽 적보다 체력 15% 증가. 접근 시차를 두고 발동. | M26: Elite | N26: 100 | O26: =ROUND(O25*(1+P26),0) -> 761 | P26: 0.15 | Q26: ='밸런스 조정'!$C$64 -> 0 | R26: ='밸런스 조정'!$C$65*IF(M26="Boss",5,IF(M26="Elite",2,1)) -> 20
B27: 25 | C27: Noryangjin_MapTool_Mode_SR18 | D27: SR18_L_E13_T149_Enemy_OldMan | E27: 1 | F27: 공격 반복 | G27: 2 | H27: 0 | I27: 8 | J27: 2 | K27: 12 | L27: 공격력·체력은 밸런스 조정 시트에서 계산. | M27: Normal | N27: =ROUND(N23*(1+'밸런스 조정'!$C$17),0) -> 4 | O27: =ROUND(O23*(1+P27),0) -> 427 | P27: ='밸런스 조정'!$C$18 -> 0.16 | Q27: ='밸런스 조정'!$C$64 -> 0 | R27: ='밸런스 조정'!$C$65*IF(M27="Boss",5,IF(M27="Elite",2,1)) -> 10
B28: 26 | C28: Noryangjin_MapTool_Mode_SR18 | D28: SR18_L_E13_T149_Enemy_OldMan_Right | E28: 1 | F28: 공격 반복 | G28: 2 | H28: 0 | I28: 5 | J28: 2 | K28: 12 | L28: 왼쪽 적보다 체력 15% 증가. 접근 시차를 두고 발동. | M28: Normal | N28: =N27 -> 4 | O28: =ROUND(O27*(1+P28),0) -> 491 | P28: 0.15 | Q28: ='밸런스 조정'!$C$64 -> 0 | R28: ='밸런스 조정'!$C$65*IF(M28="Boss",5,IF(M28="Elite",2,1)) -> 10
B29: 27 | C29: Noryangjin_MapTool_Mode_SR18 | D29: SR18_L_E14_T165_Enemy_OldMan | E29: 1 | F29: 공격 반복 | G29: 2 | H29: 0 | I29: 8 | J29: 2 | K29: 12 | L29: 공격력·체력은 밸런스 조정 시트에서 계산. | M29: Normal | N29: =ROUND(N27*(1+'밸런스 조정'!$C$17),0) -> 4 | O29: =ROUND(O27*(1+P29),0) -> 495 | P29: ='밸런스 조정'!$C$18 -> 0.16 | Q29: ='밸런스 조정'!$C$64 -> 0 | R29: ='밸런스 조정'!$C$65*IF(M29="Boss",5,IF(M29="Elite",2,1)) -> 10
B30: 28 | C30: Noryangjin_MapTool_Mode_SR18 | D30: SR18_L_E14_T165_Enemy_OldMan_Right | E30: 1 | F30: 공격 반복 | G30: 2 | H30: 0 | I30: 5 | J30: 2 | K30: 12 | L30: 왼쪽 적보다 체력 15% 증가. 접근 시차를 두고 발동. | M30: Normal | N30: =N29 -> 4 | O30: =ROUND(O29*(1+P30),0) -> 569 | P30: 0.15 | Q30: ='밸런스 조정'!$C$64 -> 0 | R30: ='밸런스 조정'!$C$65*IF(M30="Boss",5,IF(M30="Elite",2,1)) -> 10
B31: 29 | C31: Noryangjin_MapTool_Mode_SR18 | D31: SR18_L_E15_T173_Enemy_YllowMan_Sword | E31: 1 | F31: 왕복 | G31: 2.5 | H31: 8 | I31: 18 | J31: 2 | K31: 12 | L31: 공격력·체력은 밸런스 조정 시트에서 계산. | M31: Normal | N31: =ROUND(N29*(1+'밸런스 조정'!$C$17),0) -> 4 | O31: =ROUND(O29*(1+P31),0) -> 574 | P31: ='밸런스 조정'!$C$18 -> 0.16 | Q31: ='밸런스 조정'!$C$64 -> 0 | R31: ='밸런스 조정'!$C$65*IF(M31="Boss",5,IF(M31="Elite",2,1)) -> 10
B32: 30 | C32: Noryangjin_MapTool_Mode_SR18 | D32: SR18_L_E15_T173_Enemy_YllowMan_Sword_Right | E32: 1 | F32: 왕복 | G32: 2.5 | H32: 8 | I32: 14 | J32: 2 | K32: 12 | L32: 왼쪽 적보다 체력 15% 증가. 접근 시차를 두고 발동. | M32: Normal | N32: =N31 -> 4 | O32: =ROUND(O31*(1+P32),0) -> 660 | P32: 0.15 | Q32: ='밸런스 조정'!$C$64 -> 0 | R32: ='밸런스 조정'!$C$65*IF(M32="Boss",5,IF(M32="Elite",2,1)) -> 10
B33: 31 | C33: Noryangjin_MapTool_Mode_SR18 | D33: SR18_L_E16_T185_Enemy_OldMan | E33: 1 | F33: 공격 반복 | G33: 2 | H33: 0 | I33: 8 | J33: 2 | K33: 12 | L33: 공격력·체력은 밸런스 조정 시트에서 계산. | M33: Normal | N33: =ROUND(N31*(1+'밸런스 조정'!$C$17),0) -> 4 | O33: =ROUND(O31*(1+P33),0) -> 666 | P33: ='밸런스 조정'!$C$18 -> 0.16 | Q33: ='밸런스 조정'!$C$64 -> 0 | R33: ='밸런스 조정'!$C$65*IF(M33="Boss",5,IF(M33="Elite",2,1)) -> 10
B34: 32 | C34: Noryangjin_MapTool_Mode_SR18 | D34: SR18_L_E16_T185_Enemy_OldMan_Right | E34: 1 | F34: 공격 반복 | G34: 2 | H34: 0 | I34: 5 | J34: 2 | K34: 12 | L34: 왼쪽 적보다 체력 15% 증가. 접근 시차를 두고 발동. | M34: Normal | N34: =N33 -> 4 | O34: =ROUND(O33*(1+P34),0) -> 766 | P34: 0.15 | Q34: ='밸런스 조정'!$C$64 -> 0 | R34: ='밸런스 조정'!$C$65*IF(M34="Boss",5,IF(M34="Elite",2,1)) -> 10
B35: 33 | C35: Noryangjin_MapTool_Mode_SR18 | D35: SR18_L_E17_T197_Enemy_Guard | E35: 1 | F35: 전방 매복 사격 | G35: 3 | H35: 8 | I35: 16 | J35: 0.45 | K35: 11.9 | L35: 공격력·체력은 밸런스 조정 시트에서 계산. | M35: Normal | N35: =(ROUND(N33*(1+'밸런스 조정'!$C$17),0))*0.45 -> 1.8 | O35: =ROUND(O33*(1+P35),0) -> 773 | P35: ='밸런스 조정'!$C$18 -> 0.16 | Q35: ='밸런스 조정'!$C$64 -> 0 | R35: ='밸런스 조정'!$C$65*IF(M35="Boss",5,IF(M35="Elite",2,1)) -> 10
B36: 34 | C36: Noryangjin_MapTool_Mode_SR18 | D36: SR18_L_E17_T197_Enemy_Guard_Right | E36: 1 | F36: 전방 매복 사격 | G36: 3 | H36: 8 | I36: 12 | J36: 0.45 | K36: 11.9 | L36: 왼쪽 적보다 체력 15% 증가. 접근 시차를 두고 발동. | M36: Normal | N36: =N35 -> 1.8 | O36: =ROUND(O35*(1+P36),0) -> 889 | P36: 0.15 | Q36: ='밸런스 조정'!$C$64 -> 0 | R36: ='밸런스 조정'!$C$65*IF(M36="Boss",5,IF(M36="Elite",2,1)) -> 10
B37: 35 | C37: Noryangjin_MapTool_Mode_SR18 | D37: SR18_L_E18_T209_Enemy_YllowMan_Net | E37: 1 | F37: 공격 반복 | G37: 2 | H37: 0 | I37: 8 | J37: 2 | K37: 12 | L37: 공격력·체력은 밸런스 조정 시트에서 계산. | M37: Normal | N37: =ROUND(N35*(1+'밸런스 조정'!$C$17),0) -> 2 | O37: =ROUND(O35*(1+P37),0) -> 897 | P37: ='밸런스 조정'!$C$18 -> 0.16 | Q37: ='밸런스 조정'!$C$64 -> 0 | R37: ='밸런스 조정'!$C$65*IF(M37="Boss",5,IF(M37="Elite",2,1)) -> 10
B38: 36 | C38: Noryangjin_MapTool_Mode_SR18 | D38: SR18_L_E18_T209_Enemy_YllowMan_Net_Right | E38: 1 | F38: 공격 반복 | G38: 2 | H38: 0 | I38: 5 | J38: 2 | K38: 12 | L38: 왼쪽 적보다 체력 15% 증가. 접근 시차를 두고 발동. | M38: Normal | N38: =N37 -> 2 | O38: =ROUND(O37*(1+P38),0) -> 1032 | P38: 0.15 | Q38: ='밸런스 조정'!$C$64 -> 0 | R38: ='밸런스 조정'!$C$65*IF(M38="Boss",5,IF(M38="Elite",2,1)) -> 10
B39: 37 | C39: Noryangjin_MapTool_Mode_SR18 | D39: SR18_L_E19_T221_Enemy_YllowMan_Sword | E39: 1 | F39: 왕복 | G39: 1.4 | H39: 2 | I39: 18 | J39: 2 | K39: 12 | L39: 공격력·체력은 밸런스 조정 시트에서 계산. | M39: Normal | N39: =ROUND(N37*(1+'밸런스 조정'!$C$17),0) -> 2 | O39: =ROUND(O37*(1+P39),0) -> 1041 | P39: ='밸런스 조정'!$C$18 -> 0.16 | Q39: ='밸런스 조정'!$C$64 -> 0 | R39: ='밸런스 조정'!$C$65*IF(M39="Boss",5,IF(M39="Elite",2,1)) -> 10
B40: 38 | C40: Noryangjin_MapTool_Mode_SR18 | D40: SR18_L_E19_T221_Enemy_YllowMan_Sword_Right | E40: 1 | F40: 왕복 | G40: 1.4 | H40: 2 | I40: 14 | J40: 2 | K40: 12 | L40: 왼쪽 적보다 체력 15% 증가. 접근 시차를 두고 발동. | M40: Normal | N40: =N39 -> 2 | O40: =ROUND(O39*(1+P40),0) -> 1197 | P40: 0.15 | Q40: ='밸런스 조정'!$C$64 -> 0 | R40: ='밸런스 조정'!$C$65*IF(M40="Boss",5,IF(M40="Elite",2,1)) -> 10
...

Sheet 보너스 배치
B1: 값을 저장한 뒤 다음 Play부터 적용됩니다. 사용: 1=배치 유지, 0=숨김. 맵·배치ID·기믹종류는 연결용입니다.
B2: 순번 | C2: 맵 | D2: 배치ID | E2: 사용 | F2: 등급 | G2: 설명
B3: 1 | C3: Noryangjin_MapTool_Mode_SR18 | D3: SR18_L_B01_T009 | E3: 1 | F3: Normal | G3: 효과·최소·최대 수치: 보너스 시트
B4: 2 | C4: Noryangjin_MapTool_Mode_SR18 | D4: SR18_L_B02_T021 | E4: 1 | F4: Normal | G4: 효과·최소·최대 수치: 보너스 시트
B5: 3 | C5: Noryangjin_MapTool_Mode_SR18 | D5: SR18_L_B03_T033 | E5: 1 | F5: Normal | G5: 효과·최소·최대 수치: 보너스 시트
B6: 4 | C6: Noryangjin_MapTool_Mode_SR18 | D6: SR18_L_B04_T045 | E6: 1 | F6: Rare | G6: 효과·최소·최대 수치: 보너스 시트
B7: 5 | C7: Noryangjin_MapTool_Mode_SR18 | D7: SR18_L_B05_T057 | E7: 1 | F7: Normal | G7: 효과·최소·최대 수치: 보너스 시트
B8: 6 | C8: Noryangjin_MapTool_Mode_SR18 | D8: SR18_L_B06_T069 | E8: 1 | F8: Normal | G8: 효과·최소·최대 수치: 보너스 시트
B9: 7 | C9: Noryangjin_MapTool_Mode_SR18 | D9: SR18_L_B07_T081 | E9: 1 | F9: Normal | G9: 효과·최소·최대 수치: 보너스 시트
B10: 8 | C10: Noryangjin_MapTool_Mode_SR18 | D10: SR18_L_B08_T093 | E10: 1 | F10: Rare | G10: 효과·최소·최대 수치: 보너스 시트
B11: 9 | C11: Noryangjin_MapTool_Mode_SR18 | D11: SR18_L_B09_T105 | E11: 1 | F11: Normal | G11: 효과·최소·최대 수치: 보너스 시트
B12: 10 | C12: Noryangjin_MapTool_Mode_SR18 | D12: SR18_L_B10_T117 | E12: 1 | F12: Normal | G12: 효과·최소·최대 수치: 보너스 시트
B13: 11 | C13: Noryangjin_MapTool_Mode_SR18 | D13: SR18_L_B11_T129 | E13: 1 | F13: Normal | G13: 효과·최소·최대 수치: 보너스 시트
B14: 12 | C14: Noryangjin_MapTool_Mode_SR18 | D14: SR18_L_B12_T141 | E14: 1 | F14: Rare | G14: 효과·최소·최대 수치: 보너스 시트
... B65: 68 | C65: RestStop | D65: RST_B18 | E65: 1 | F65: Normal | G65: 좌우 중 하나 선택

Sheet 기믹 배치
B1: 값을 저장한 뒤 다음 Play부터 적용됩니다. 사용: 1=배치 유지, 0=숨김. 맵·배치ID·기믹종류는 연결용입니다.
B2: 순번 | C2: 맵 | D2: 배치ID | E2: 사용 | F2: 기믹종류 | G2: 효과값 | H2: 설명 | I2: 내구도 | J2: 예고초 | K2: 작동초 | L2: 이동폭
B3: 1 | C3: Noryangjin_MapTool_Mode_SR18 | D3: SR18_L_G01_T013_Bucket | E3: 0 | F3: Bucket | G3: 3 | H3: 3개 묶음 전체에 적용. 효과값: 바구니별 사격 금지 시간(초).
B4: 2 | C4: Noryangjin_MapTool_Mode_SR18 | D4: SR18_L_G02_T025_Light | E4: 1 | F4: Light | G4: 50 | H4: 효과값: 접촉 피해량. 기믹종류는 모델 확인용.
B5: 3 | C5: Noryangjin_MapTool_Mode_SR18 | D5: SR18_L_G03_T037_Hole | E5: 1 | F5: Hole | G5: 80 | H5: 파손된 판자 · 피해80, 생존하면 전진 유지
B6: 4 | C6: Noryangjin_MapTool_Mode_SR18 | D6: SR18_L_G04_T049_Bucket | E6: 1 | F6: Bucket | G6: 3 | H6: 3개 묶음 전체에 적용. 효과값: 바구니별 사격 금지 시간(초).
B7: 5 | C7: Noryangjin_MapTool_Mode_SR18 | D7: SR18_L_G05_T061_Light | E7: 1 | F7: Light | G7: 50 | H7: 효과값: 접촉 피해량. 기믹종류는 모델 확인용.
B8: 6 | C8: Noryangjin_MapTool_Mode_SR18 | D8: SR18_L_G06_T073_Hole | E8: 1 | F8: Hole | G8: 80 | H8: 파손된 판자 · 피해80, 생존하면 전진 유지
B9: 7 | C9: Noryangjin_MapTool_Mode_SR18 | D9: SR18_L_G07_T085_Bucket | E9: 1 | F9: Bucket | G9: 3 | H9: 3개 묶음 전체에 적용. 효과값: 바구니별 사격 금지 시간(초).
B10: 8 | C10: Noryangjin_MapTool_Mode_SR18 | D10: SR18_L_G08_T097_Oldman | E10: 1 | F10: Oldman | G10: ='밸런스 조정'!$C$67 -> 12 | H10: 노에 닿으면 피해를 받고 모델만 회전. 진행과 카메라 유지.
B11: 9 | C11: Noryangjin_MapTool_Mode_SR18 | D11: SR18_L_G09_T109_Hole | E11: 1 | F11: Hole | G11: 80 | H11: 파손된 판자 · 피해80, 생존하면 전진 유지
B12: 10 | C12: Noryangjin_MapTool_Mode_SR18 | D12: SR18_L_G10_T121_Oil | E12: 1 | F12: Oil | G12: ='밸런스 조정'!$C$48 -> 2 | H12: 잠시 좌우 조작 감소. 진행 방향과 사격 유지.
B13: 11 | C13: Noryangjin_MapTool_Mode_SR18 | D13: SR18_L_G11_T133_Light | E13: 1 | F13: Light | G13: 50 | H13: 효과값: 접촉 피해량. 기믹종류는 모델 확인용.
B14: 12 | C14: Noryangjin_MapTool_Mode_SR18 | D14: SR18_L_G12_T145_Hole | E14: 1 | F14: Hole | G14: 80 | H14: 파손된 판자 · 피해80, 생존하면 전진 유지
B15: 13 | C15: Noryangjin_MapTool_Mode_SR18 | D15: SR18_L_G13_T157_Bucket | E15: 1 | F15: Bucket | G15: 3 | H15: 3개 묶음 전체에 적용. 효과값: 바구니별 사격 금지 시간(초).
B16: 14 | C16: Noryangjin_MapTool_Mode_SR18 | D16: SR18_L_G14_T169_Light | E16: 1 | F16: Light | G16: 50 | H16: 효과값: 접촉 피해량. 기믹종류는 모델 확인용.
B17: 15 | C17: Noryangjin_MapTool_Mode_SR18 | D17: SR18_L_G15_T181_Bucket | E17: 1 | F17: Bucket | G17: 3 | H17: 3개 묶음 전체에 적용. 효과값: 바구니별 사격 금지 시간(초).
B18: 16 | C18: Noryangjin_MapTool_Mode_SR18 | D18: SR18_L_G16_T193_Seagull | E18: 1 | F18: Seagull | G18: ='밸런스 조정'!$C$49 -> 20 | H18: 그림자 예고 후 갈매기 급강하
B19: 17 | C19: Noryangjin_MapTool_Mode_SR18 | D19: SR18_L_G17_T205_Dolphin | E19: 1 | F19: Dolphin | G19: ='밸런스 조정'!$C$68 -> 3 | H19: 물가 점프 높이(m). 접촉 피해 없음.
B20: 18 | C20: Noryangjin_MapTool_Mode_SR18 | D20: SR18_L_G18_T217_Hole | E20: 1 | F20: Hole | G20: 80 | H20: 파손된 판자 · 피해80, 생존하면 전진 유지
B21: 19 | C21: Noryangjin_MapTool_Mode_SR18 | D21: SR18_L_G19_T229_Oil | E21: 1 | F21: Oil | G21: ='밸런스 조정'!$C$48 -> 2 | H21: 잠시 좌우 조작 감소. 진행 방향과 사격 유지.
B22: 20 | C22: Noryangjin_MapTool_Mode_SR18 | D22: SR18_L_G20_T241_Light | E22: 1 | F22: Light | G22: 50 | H22: 효과값: 접촉 피해량. 기믹종류는 모델 확인용.
B23: 21 | C23: Noryangjin_MapTool_Mode_SR18 | D23: SR18_L_G21_T253_Hole | E23: 1 | F23: Hole | G23: 80 | H23: 파손된 판자 · 피해80, 생존하면 전진 유지
B24: 22 | C24: Noryangjin_MapTool_Mode_SR18 | D24: SR18_L_G22_T265_Bucket | E24: 1 | F24: Bucket | G24: 3 | H24: 3개 묶음 전체에 적용. 효과값: 바구니별 사격 금지 시간(초).
B25: 23 | C25: Noryangjin_MapTool_Mode_SR18 | D25: SR18_L_G23_T277_Light | E25: 1 | F25: Light | G25: 50 | H25: 효과값: 접촉 피해량. 기믹종류는 모델 확인용.
B26: 24 | C26: Noryangjin_MapTool_Mode_SR18 | D26: SR18_L_G24_T289_Hole | E26: 1 | F26: Hole | G26: 80 | H26: 파손된 판자 · 피해80, 생존하면 전진 유지
B27: 25 | C27: Noryangjin_MapTool_Mode_SR18 | D27: SR18_Polish_Ship_2 | E27: 1 | F27: Ship | G27: ='밸런스 조정'!$C$50 -> 10 | H27: 해안에서 진행로를 향한 포격
B28: 26 | C28: HighWay | D28: HWY_G01_Roadblock | E28: 0 | F28: HighwayRoadblock | G28: ='밸런스 조정'!$C$38 -> 180 | H28: 예고와 진행 간격을 확보한 고속도로 장애물 | I28: ='밸런스 조정'!$C$41 -> 240 | J28: ='밸런스 조정'!$C$42 -> 1.8 | K28: ='밸런스 조정'!$C$43 -> 4 | L28: =0 -> 0
B29: 27 | C29: HighWay | D29: HWY_G02_Roadblock | E29: 0 | F29: HighwayRoadblock | G29: ='밸런스 조정'!$C$38 -> 180 | H29: 예고와 진행 간격을 확보한 고속도로 장애물 | I29: ='밸런스 조정'!$C$41 -> 240 | J29: ='밸런스 조정'!$C$42 -> 1.8 | K29: ='밸런스 조정'!$C$43 -> 4 | L29: =0 -> 0
B30: 28 | C30: HighWay | D30: HWY_G03_Roadblock | E30: 0 | F30: HighwayRoadblock | G30: ='밸런스 조정'!$C$38 -> 180 | H30: 예고와 진행 간격을 확보한 고속도로 장애물 | I30: ='밸런스 조정'!$C$41 -> 240 | J30: ='밸런스 조정'!$C$42 -> 1.8 | K30: ='밸런스 조정'!$C$43 -> 4 | L30: =0 -> 0
B31: 29 | C31: HighWay | D31: HWY_G04_Roadblock | E31: 0 | F31: HighwayRoadblock | G31: ='밸런스 조정'!$C$38 -> 180 | H31: 예고와 진행 간격을 확보한 고속도로 장애물 | I31: ='밸런스 조정'!$C$41 -> 240 | J31: ='밸런스 조정'!$C$42 -> 1.8 | K31: ='밸런스 조정'!$C$43 -> 4 | L31: =0 -> 0
B32: 30 | C32: HighWay | D32: HWY_G05_Roadblock | E32: 0 | F32: HighwayRoadblock | G32: ='밸런스 조정'!$C$38 -> 180 | H32: 예고와 진행 간격을 확보한 고속도로 장애물 | I32: ='밸런스 조정'!$C$41 -> 240 | J32: ='밸런스 조정'!$C$42 -> 1.8 | K32: ='밸런스 조정'!$C$43 -> 4 | L32: =0 -> 0
B33: 31 | C33: HighWay | D33: HWY_G06_Roadblock | E33: 0 | F33: HighwayRoadblock | G33: ='밸런스 조정'!$C$38 -> 180 | H33: 예고와 진행 간격을 확보한 고속도로 장애물 | I33: ='밸런스 조정'!$C$41 -> 240 | J33: ='밸런스 조정'!$C$42 -> 1.8 | K33: ='밸런스 조정'!$C$43 -> 4 | L33: =0 -> 0
B34: 32 | C34: HighWay | D34: HWY_G07_Roadblock | E34: 0 | F34: HighwayRoadblock | G34: ='밸런스 조정'!$C$38 -> 180 | H34: 예고와 진행 간격을 확보한 고속도로 장애물 | I34: ='밸런스 조정'!$C$41 -> 240 | J34: ='밸런스 조정'!$C$42 -> 1.8 | K34: ='밸런스 조정'!$C$43 -> 4 | L34: =0 -> 0
B35: 33 | C35: HighWay | D35: HWY_G08_Roadblock | E35: 0 | F35: HighwayRoadblock | G35: ='밸런스 조정'!$C$38 -> 180 | H35: 예고와 진행 간격을 확보한 고속도로 장애물 | I35: ='밸런스 조정'!$C$41 -> 240 | J35: ='밸런스 조정'!$C$42 -> 1.8 | K35: ='밸런스 조정'!$C$43 -> 4 | L35: =0 -> 0
B36: 34 | C36: HighWay | D36: HWY_G09_Roadblock | E36: 0 | F36: HighwayRoadblock | G36: ='밸런스 조정'!$C$38 -> 180 | H36: 예고와 진행 간격을 확보한 고속도로 장애물 | I36: ='밸런스 조정'!$C$41 -> 240 | J36: ='밸런스 조정'!$C$42 -> 1.8 | K36: ='밸런스 조정'!$C$43 -> 4 | L36: =0 -> 0
B37: 35 | C37: HighWay | D37: HWY_G10_Roadblock | E37: 0 | F37: HighwayRoadblock | G37: ='밸런스 조정'!$C$38 -> 180 | H37: 예고와 진행 간격을 확보한 고속도로 장애물 | I37: ='밸런스 조정'!$C$41 -> 240 | J37: ='밸런스 조정'!$C$42 -> 1.8 | K37: ='밸런스 조정'!$C$43 -> 4 | L37: =0 -> 0
B38: 36 | C38: HighWay | D38: HWY_G11_Roadblock | E38: 0 | F38: HighwayRoadblock | G38: ='밸런스 조정'!$C$38 -> 180 | H38: 예고와 진행 간격을 확보한 고속도로 장애물 | I38: ='밸런스 조정'!$C$41 -> 240 | J38: ='밸런스 조정'!$C$42 -> 1.8 | K38: ='밸런스 조정'!$C$43 -> 4 | L38: =0 -> 0
B39: 37 | C39: HighWay | D39: HWY_G12_Roadblock | E39: 0 | F39: HighwayRoadblock | G39: ='밸런스 조정'!$C$38 -> 180 | H39: 예고와 진행 간격을 확보한 고속도로 장애물 | I39: ='밸런스 조정'!$C$41 -> 240 | J39: ='밸런스 조정'!$C$42 -> 1.8 | K39: ='밸런스 조정'!$C$43 -> 4 | L39: =0 -> 0
... B41: 39 | C41: HighWay | D41: HWY_G14_Roadblock | E41: 0 | F41: HighwayRoadblock | G41: ='밸런스 조정'!$C$38 -> 180 | H41: 예고와 진행 간격을 확보한 고속도로 장애물 | I41: ='밸런스 조정'!$C$41 -> 240 | J41: ='밸런스 조정'!$C$42 -> 1.8 | K41: ='밸런스 조정'!$C$43 -> 4 | L41: =0 -> 0
...

Sheet 밸런스 조정
B1: 노량진 성장과 구매 비용
B2: 항목 | C2: 기본값 | D2: 레벨당 증가 | E2: 첫 가격 | F2: 가격 증가 | G2: 수치 타입 | H2: 가격 타입
B3: ATT | C3: 0 | D3: 4 | E3: 10 | F3: 5 | G3: value | H3: Coin
B4: HP | C4: 0 | D4: 20 | E4: 10 | F4: 5 | G4: value | H4: Coin
B5: ATT_SPEED | C5: 0 | D5: 5 | E5: 45 | F5: 20 | G5: percent | H5: Coin
B6: PROJECTILE_SPEED | C6: 0 | D6: 4 | E6: 40 | F6: 16 | G6: percent | H6: Coin
B7: BOSS_DAMAGE | C7: 0 | D7: 8 | E7: 60 | F7: 25 | G7: percent | H7: Coin
B8: COIN_BONUS | C8: 0 | D8: 8 | E8: 70 | F8: 35 | G8: percent | H8: Coin
B9: HP_REGEN | C9: 0 | D9: 0.1 | E9: 80 | F9: 35 | G9: value | H9: Coin
B10: TUNGTUNGTUNG | C10: 95 | D10: 5 | E10: 450 | F10: 120 | G10: percent | H10: Coin
B11: BOOMBAR | C11: 125 | D11: 5 | E11: 550 | F11: 150 | G11: percent | H11: Coin
B14: 적 성장 기준 | C14: 값
B15: 첫 일반 공격력 | C15: 8
B16: 첫 일반 체력 | C16: 45
B17: 일반 공격력 증가율 | C17: 0.04
B18: 일반 체력 증가율 | C18: 0.16
B19: 엘리트 공격력 배수 | C19: 1.6
B20: 엘리트 체력 배수 | C20: 1.8
B21: 보스 공격력 배수 | C21: 3
B22: 보스 체력 배수 | C22: 1.31
B23: 두 번째 일반 적 체력 | C23: 55
B24: 첫 성장 벽 체력 | C24: 130
B25: 약 20회 도전 목표. 첫 도전 약 30초, 실제 획득 코인과 업그레이드 구매로 진행을 검증.
B28: 고속도로 전투와 기믹
B29: 항목 | C29: 값 | D29: 설명
B30: 첫 일반 공격력 | C30: 220 | D30: 투사체 기본 피해
B31: 첫 일반 체력 | C31: 500 | D31: 첫 전투 기준
B32: 공격력 증가율 | C32: 0.035 | D32: 배치 순서마다 증가
B33: 체력 증가율 | C33: 0.075 | D33: 배치 순서마다 증가
B34: 엘리트 공격력 배수 | C34: 1.25 | D34: 일반 성장값에 적용
B35: 엘리트 체력 배수 | C35: 1.5 | D35: 일반 성장값에 적용
B36: 보스 공격력 배수 | C36: 1.8 | D36: 마지막 대장에 적용
B37: 보스 체력 배수 | C37: 1.85 | D37: 마지막 대장에 적용
B38: 도로 장애물 피해 | C38: 180 | D38: 충돌 시 피해
B39: 차량 충돌 피해 | C39: 240 | D39: 횡단 차량의 피해
B40: 차단기 충돌 피해 | C40: 280 | D40: 닫힌 차단기의 피해
B41: 장애물 내구도 | C41: 240 | D41: 사격으로 부술 수 있음
... B45: 차량 이동 폭 | C45: 9 | D45: 좌우 횡단 거리
B47: 노량진 추가 기믹
B48: 기름 웅덩이 지속 시간 | C48: 2 | D48: 조작 감도 55%, 중첩 없음
...

Sheet 커스터마이징
B1: 상어의 피부·신발·모자. 장착한 세 부위의 효과가 함께 적용됩니다.
B2: ID | C2: 부위 | D2: 이름 | E2: 가격타입 | F2: 가격 | G2: 비주얼 | H2: 기본 | I2: 설명 | J2: 효과 | K2: 효과값 | L2: 효과타입
B3: skin_original | C3: Skin | D3: 저주받은 상어 | E3: Jewel | F3: 0 | G3: skin_original | H3: 1 | I3: 훔친 신발이 남긴 푸른 저주의 흔적 | K3: 0 | L3: Percent
B4: skin_coral | C4: Skin | D4: 벚꽃 상어 | E4: Jewel | F4: 250 | G4: skin_coral | H4: 0 | I4: 은은한 분홍빛과 밝은 배색의 상어 | J4: HP | K4: 20 | L4: Percent
B5: skin_ice | C5: Skin | D5: 빙하 상어 | E5: Jewel | F5: 350 | G5: skin_ice | H5: 0 | I5: 얼음처럼 갈라진 차가운 피부 문양 | J5: ATT_SPEED | K5: 20 | L5: Percent
B6: skin_sand | C6: Skin | D6: 오래된 유목 | E6: Jewel | F6: 450 | G6: skin_sand | H6: 0 | I6: 오랜 항해를 닮은 나뭇결 문양 | J6: HP | K6: 32 | L6: Percent
B7: skin_armor | C7: Skin | D7: 해안 경비대 | E7: Jewel | F7: 700 | G7: skin_armor | H7: 0 | I7: 해안 위장무늬와 단단한 인상 | J7: HP | K7: 48 | L7: Percent
B8: skin_raider | C8: Skin | D8: 심해 생존자 | E8: Jewel | F8: 600 | G8: skin_raider | H8: 0 | I8: 깊은 바다에서 돌아온 거친 피부 | J8: ATT | K8: 32 | L8: Percent
B9: skin_relic | C9: Skin | D9: 용암의 심장 | E9: Jewel | F9: 900 | G9: skin_relic | H9: 0 | I9: 검은 표면 사이로 흐르는 붉은 균열 | J9: BOSS_DAMAGE | K9: 48 | L9: Percent
B10: skin_diver | C10: Skin | D10: 네온 잠수부 | E10: Jewel | F10: 650 | G10: skin_diver | H10: 0 | I10: 회로와 금속 패널이 이어진 피부 | J10: HP_REGEN | K10: 0.6 | L10: Value
B11: shoes_original | C11: Shoes | D11: 푸른 운동화 | E11: Jewel | F11: 0 | G11: shoes_original | H11: 1 | I11: 저주의 시작이 된 푸른 운동화 | K11: 0 | L11: Percent
B12: shoes_ruby | C12: Shoes | D12: 코퍼 하이탑 | E12: Jewel | F12: 200 | G12: shoes_ruby | H12: 0 | I12: 통풍 패널과 구리빛 포인트의 하이탑 | J12: ATT | K12: 16 | L12: Percent
B13: shoes_mint | C13: Shoes | D13: 폴라 부츠 | E13: Jewel | F13: 300 | G13: shoes_mint | H13: 0 | I13: 퀼팅 원단과 두툼한 방한 칼라 | J13: ATT_SPEED | K13: 16 | L13: Percent
B14: shoes_gold | C14: Shoes | D14: 선장 로퍼 | E14: Jewel | F14: 400 | G14: shoes_gold | H14: 0 | I14: 짙은 가죽과 황동 버클의 갑판화 | J14: COIN_BONUS | K14: 24 | L14: Percent
B15: shoes_steel | C15: Shoes | D15: 강철 워커 | E15: Jewel | F15: 600 | G15: shoes_steel | H15: 0 | I15: 금속 앞코와 튼튼한 작업용 밑창 | J15: ATT | K15: 32 | L15: Percent
B16: shoes_spring | C16: Shoes | D16: 스프링 러너 | E16: Jewel | F16: 750 | G16: shoes_spring | H16: 0 | I16: 탄성 프레임을 갖춘 가벼운 러닝화 | J16: ATT_SPEED | K16: 32 | L16: Percent
B17: shoes_relic | C17: Shoes | D17: 파도 유물화 | E17: Jewel | F17: 900 | G17: shoes_relic | H17: 0 | I17: 파도 장식과 푸른 보석의 유물 부츠 | J17: PROJECTILE_SPEED | K17: 40 | L17: Percent
B18: shoes_salvage | C18: Shoes | D18: 잠수 작업화 | E18: Jewel | F18: 650 | G18: shoes_salvage | H18: 0 | I18: 잠수 장비를 닮은 단단한 작업화 | J18: COIN_BONUS | K18: 40 | L18: Percent
B19: hat_none | C19: Hat | D19: 머리 장비 없음 | E19: Jewel | F19: 0 | G19: hat_none | H19: 1 | I19: 저주만으로도 충분히 무겁다 | K19: 0 | L19: Percent
B20: hat_cap | C20: Hat | D20: 항해사 캡 | E20: Jewel | F20: 250 | G20: hat_cap | H20: 0 | I20: 항해사의 실용적인 캔버스 캡 | J20: COIN_BONUS | K20: 16 | L20: Percent
B21: hat_bucket | C21: Hat | D21: 방수 버킷햇 | E21: Jewel | F21: 350 | G21: hat_bucket | H21: 0 | I21: 짙은 청록색의 넓은 방수 챙 | J21: HP | K21: 20 | L21: Percent
B22: hat_tophat | C22: Hat | D22: 야간 정비사 | E22: Jewel | F22: 500 | G22: hat_tophat | H22: 0 | I22: 정비 장식이 달린 작업용 톱햇 | J22: BOSS_DAMAGE | K22: 32 | L22: Percent
B23: hat_goggles | C23: Hat | D23: 야간 고글 | E23: Jewel | F23: 650 | G23: hat_goggles | H23: 0 | I23: 황동 프레임과 짙은 렌즈 | J23: ATT | K23: 24 | L23: Percent
B24: hat_diver | C24: Hat | D24: 황동 잠수모 | E24: Jewel | F24: 850 | G24: hat_diver | H24: 0 | I24: 얼굴이 보이는 개방형 황동 잠수모 | J24: HP | K24: 40 | L24: Percent
B25: hat_pirate | C25: Hat | D25: 검은 돛 선장모 | E25: Jewel | F25: 750 | G25: hat_pirate | H25: 0 | I25: 해진 가죽과 나침반 장식의 삼각모 | J25: PROJECTILE_SPEED | K25: 32 | L25: Percent
B26: hat_relic | C26: Hat | D26: 파도의 관 | E26: Jewel | F26: 1000 | G26: hat_relic | H26: 0 | I26: 짧은 파도 장식과 터키석의 금빛 관 | J26: BOSS_DAMAGE | K26: 48 | L26: Percent
