Workbook

Sheet 캠페인_요약
A1: 5개 독립 챕터 · 20분 직선·꺾임 축척 설계
A2: 사용자 스케치처럼 긴 직선으로 시간을 확보하고, 시야와 배경을 바꿀 때만 큰 90도 코너를 둡니다. 빨강 노량진 END가 파랑 고속도로 START입니다.
A4: 챕터 | E4: 표시 합계 | I4: 최장 챕터 | M4: 재시작 기준
A5: =설정_계산!B10 -> 5 | E5: =설정_계산!D10 -> 20:00 | I5: =MAX(설정_계산!$C$5:$C$9)/60 -> 5 | M5: 현재 챕터
A7: 개 | E7: 연속 플레이 아님 | I7: 분 | M7: 클리어 저장
A9: 진행 구조
A10: 1. 챕터 선택 | E10: 2. 사망 | I10: 3. 클리어 | M10: 4. 휴게소
A11: 해금된 가장 최근 챕터부터 시작 가능 | E11: 현재 챕터 시작점으로만 복귀 | I11: 다음 챕터 해금·클리어 상태 저장 | M11: 2분 완충: 회복·상점·짧은 방어
A14: No | B14: 챕터 | C14: 목표(초) | D14: 목표(분) | E14: 구현 상태 | F14: 사망 시 | G14: 핵심 동선 | H14: 피날레 | I14: 설계 근거 | K14: 새 목표시간
A15: 1 | B15: 노량진 | C15: =설정_계산!C5 -> 270 | D15: =C15/60 -> 4.5 | E15: 실측 기반 | F15: 현재 챕터 재시작 | G15: 현재 길 왼쪽→위 · 대형 사각 우회 | H15: 방파제 보스 부두 | I15: Noryangjin_MapTool_Mode.unity + 기존 5분 상세본
A16: 2 | B16: 고속도로 | C16: =설정_계산!C6 -> 240 | D16: =C16/60 -> 4 | E16: 기존 씬 기반 제안 | F16: 현재 챕터 재시작 | G16: 상행 장거리 · 좌측 장거리 · 합류 직선 | H16: 터널·대형 차량 매복 | I16: Stage02_Highway_AutoDraft.unity + Stage02 에셋
A17: 3 | B17: 휴게소 | C17: =설정_계산!C7 -> 120 | D17: =C17/60 -> 2 | E17: 문서 기반 신규 제안 | F17: 현재 챕터 재시작 | G17: 진입 직선 · 주차 회차 · 출구 직선 | H17: 출구 30초 방어 | I17: Stage03 Rest Stop 설계 문서 | K17: 4:30 → 4:00 → 2:00 → 4:30 → 5:00
A18: 4 | B18: 도심 | C18: =설정_계산!C8 -> 270 | D18: =C18/60 -> 4.5 | E18: 문서 기반 신규 제안 | F18: 현재 챕터 재시작 | G18: 긴 대로 · 큰 교차로 · 공사 우회 | H18: 대형 교차로 엘리트전 | I18: Stage04 City 설계 문서
A19: 5 | B19: 백화점 | C19: =설정_계산!C9 -> 300 | D19: =C19/60 -> 5 | E19: 문서 기반 신규 제안 | F19: 현재 챕터 재시작 | G19: 명품대로 · 발렛 꺾임 · 정문 진입 | H19: 백화점 입구 최종 보스 | I19: Stage05 Gangnam/Department Store 설계 문서
K21: 휴게소만 2분 완충 구간 상점 · 회복 · 짧은 방어전
A22: 판정: 현재 21모듈을 4분30초로 보이게 늘린 것이 아닙니다. 노량진 142모듈을 실제로 배치하고, 7개의 큰 코너 사이를 긴 직선으로 연결했습니다.
A27: 시간 검증값은 유지됩니다. 작은 반복 지그재그 없이 총 626모듈·약 7,027u를 직선과 큰 꺾임으로 배치하며, MapTool과 Unity 씬은 수정하지 않습니다.

Sheet 사용자_스케치_해석
A1: 사용자 스케치 해석 · 빨강 노량진 / 파랑 고속도로
A3: 핵심은 미로형 커브가 아니라, 현재 씬보다 훨씬 긴 직선과 필요한 지점의 큰 90도 꺾임입니다.
H5: 스케치에서 읽은 설계 규칙
H7: 1 | I7: 현재 노량진 씬은 전체 빨간 길의 일부일 뿐입니다.
H9: 2 | I9: 빨간 노량진 END와 파란 고속도로 START는 같은 점입니다.
H11: 3 | I11: 직선은 길게, 꺾임은 크게. 짧은 지그재그는 넣지 않습니다.
H13: 4 | I13: 시간은 코너 수가 아니라 실제 모듈 길이로 확보합니다.
H15: 5 | I15: 각 코너는 배경·적 조합·오브젝트가 바뀌는 구간 전환점입니다.
A22: 시간·길이·코너 밀도
A23: CH | B23: 구간 | D23: 시간 | E23: 모듈 | F23: 지도셀 | G23: 큰 코너 | H23: 코너 간 평균 | I23: 최장 직선 | J23: 전환점 | K23: 설계 판단
A24: 1 | B24: 노량진 | D24: 4:30 | E24: 142 | F24: 71 | G24: 7 | H24: 약 34초 | I24: 19셀 | J24: 다음 START | K24: 현재 길 왼쪽→위 · 이후 대형 사각 우회
A25: 2 | B25: 고속도로 | D25: 4:00 | E25: 125 | F25: 63 | G25: 3 | H25: 약 60초 | I25: 17셀 | J25: 다음 START | K25: 상행 장거리 · 좌측 장거리 · 합류 직선
A26: 3 | B26: 휴게소 | D26: 2:00 | E26: 61 | F26: 31 | G26: 4 | H26: 약 24초 | I26: 11셀 | J26: 다음 START | K26: 진입 직선 · 주차 회차 · 출구 직선
A27: 4 | B27: 도심 | D27: 4:30 | E27: 141 | F27: 71 | G27: 5 | H27: 약 45초 | I27: 23셀 | J27: 다음 START | K27: 긴 대로 · 큰 교차로 · 공사 우회
A28: 5 | B28: 백화점 | D28: 5:00 | E28: 157 | F28: 79 | G28: 5 | H28: 약 50초 | I28: 23셀 | J28: 최종 END | K28: 명품대로 · 발렛 꺾임 · 정문 진입
A30: 현재 노량진은 21모듈·약 43.5초입니다. 4분30초 목표는 142모듈이므로, 빨간 길 전체는 현재 길의 약 6.8배가 되어야 합니다. 이번 안은 이 비율을 유지하면서 노량진 7개, 고속도로 3개, 휴게소 4개, 도심 5개, 백화점 5개의 큰 코너만 사용합니다.

Sheet 챕터_연결도
A1: 사용자 스케치 기준 연속 동선 · 긴 직선 + 절제된 큰 코너
A3: S는 사용자가 표시한 노량진 시작점입니다. 녹색 11셀은 현재 21모듈, 빨간색 나머지는 노량진 확장, T1부터 파란색 고속도로가 같은 점에서 시작합니다.
B5: CH.1 노량진 4:30 142모듈 · 큰 코너 7개 · 코너 간 평균 34초 | Q5: CH.2 고속도로 4:00 125모듈 · 큰 코너 3개 · 코너 간 평균 60초 | AF5: CH.3 휴게소 2:00 61모듈 · 큰 코너 4개 · 코너 간 평균 24초 | AU5: CH.4 도심 4:30 141모듈 · 큰 코너 5개 · 코너 간 평균 45초 | BJ5: CH.5 백화점 5:00 157모듈 · 큰 코너 5개 · 코너 간 평균 50초
D13: · | E13: 60 | F13: · | G13: · | H13: · | I13: · | J13: · | K13: · | L13: · | M13: · | N13: · | O13: 40 | P13: · | Q13: · | R13: · | S13: · | T13: · | U13: ·
D14: · | U14: ·
D15: · | U15: ·
D16: · | U16: ·
D17: · | U17: 20
D18: · | U18: ·
D19: · | U19: ·
D20: · | U20: ·
D21: · | U21: ·
D22: 80 | U22: · | BG22: · | BH22: · | BI22: · | BJ22: 100 | BK22: · | BL22: · | BM22: · | BN22: · | BO22: · | BP22: · | BQ22: · | BR22: · | BS22: · | BT22: 80 | BU22: ·
D23: · | U23: · | BG23: · | BU23: ·
D24: · | U24: · | BG24: · | BU24: ·
D25: · | U25: · | BG25: · | BU25: ·
D26: · | U26: T1 | BG26: · | BU26: ·
D27: · | U27: 140 | BG27: · | BU27: ·
D28: · | E28: · | F28: · | G28: · | H28: 100 | I28: · | J28: · | K28: · | L28: · | M28: · | N28: · | O28: · | P28: · | Q28: · | R28: 120 | S28: · | T28: · | U28: T2 | V28: · | W28: · | X28: · | Y28: · | BG28: · | BU28: ·
U29: · | Y29: · | BG29: 120 | BU29: ·
M30: T3 | U30: · | Y30: · | AI30: 21 | AJ30: · | AK30: · | AL30: · | AM30: · | AN30: · | AO30: · | AP30: · | AQ30: · | AR30: 40 | BG30: · | BU30: ·
M31: · | U31: · | Y31: · | AI31: 20 | AR31: · | BG31: · | BU31: 60
J32: · | K32: · | L32: · | M32: · | U32: · | Y32: · | AI32: · | AR32: · | BG32: · | BU32: ·
J33: · | M33: · | U33: · | Y33: 120 | AI33: · | AJ33: 현재씬 | AR33: · | BG33: · | BH33: · | BI33: · | BJ33: · | BK33: · | BL33: · | BM33: 140 | BN33: · | BO33: · | BP33: · | BU33: ·
J34: · | M34: · | U34: · | Y34: · | AI34: · | AR34: · | BP34: · | BU34: ·
J35: · | M35: · | U35: · | Y35: · | AI35: · | AR35: · | BP35: · | BU35: ·
J36: · | M36: · | U36: · | Y36: · | AI36: · | AJ36: · | AK36: · | AL36: · | AM36: S | AR36: · | BP36: · | BU36: ·
J37: · | K37: 40 | L37: · | M37: · | N37: · | O37: · | P37: · | Q37: · | R37: · | S37: · | T37: · | U37: 20 | Y37: · | AR37: · | BP37: · | BU37: ·
M38: · | Y38: · | AR38: · | BP38: · | BU38: ·
M39: 20 | Y39: · | AR39: · | BP39: E | BU39: ·
M40: · | Y40: · | AR40: 60 | BU40: ·
M41: · | Y41: · | AR41: · | BU41: 40
M42: · | Y42: · | Z42: 100 | AA42: · | AB42: · | AC42: · | AD42: · | AE42: · | AF42: · | AG42: · | AH42: · | AI42: · | AJ42: 80 | AK42: · | AL42: · | AM42: · | AN42: · | AO42: · | AP42: · | AQ42: · | AR42: · | BU42: ·
M43: · | BU43: ·
M44: · | BU44: ·
M45: · | BD45: · | BE45: 140 | BF45: T4 | BG45: · | BH45: · | BI45: · | BJ45: · | BK45: · | BL45: · | BM45: · | BN45: · | BO45: 20 | BP45: · | BQ45: · | BR45: · | BS45: · | BT45: · | BU45: ·
M46: · | N46: · | O46: · | P46: 40 | Q46: · | R46: · | S46: · | T46: · | U46: · | V46: · | W46: · | X46: · | Y46: · | Z46: 60 | AA46: · | AB46: · | AC46: · | AD46: · | AE46: · | AF46: · | AG46: · | AH46: · | AI46: · | AJ46: 80 | BD46: ·
AJ47: · | BD47: ·
AJ48: · | BD48: ·
AJ49: · | BD49: ·
...

Sheet 01_노량진_4분30초
A1: CH.1 노량진 · 4:30 직선·꺾임 축척 맵
A2: 현재 열린 노량진맵툴1의 21도로·170오브젝트 매치를 기준으로, 긴 직선과 7개 큰 코너의 142모듈 전체에 밀도를 완화해 확장합니다.
B4: 목표시간 | I4: 구현 상태 | P4: 동선 구조 | X4: 피날레
B5: 4:30 | I5: 실측 기반 | P5: 최장 직선 23셀 · 코너 간 평균 34초 | X5: 방파제 보스 부두
B7: 다이나믹 축척 1셀=2모듈 | J7: 현재 길 왼쪽→위 · 이후 대형 사각 우회 | T7: 142모듈 · 71셀 · 큰 코너 7개 | AI7: 단계 색상·시간
AI9: P1 0:00–0:40 기존 하단→세로 부두
H10: · | I10: · | J10: · | K10: P4 | L10: · | M10: · | N10: 80 | O10: · | P10: · | Q10: · | R10: · | S10: · | T10: · | U10: · | V10: · | W10: · | X10: 60 | Y10: P3 | Z10: · | AA10: · | AB10: · | AC10: · | AD10: · | AE10: ·
H11: · | AE11: ·
H12: · | AE12: · | AI12: P2 0:40–1:30 상단 동쪽 경매 부두
H13: · | AE13: 40
H14: 100 | AE14: ·
H15: · | T15: E | AE15: · | AI15: P3 1:30–2:25 냉동창고 역방향
H16: · | T16: 140 | Y16: 21 | Z16: · | AA16: · | AB16: · | AC16: P2 | AD16: · | AE16: ·
H17: · | T17: · | Y17: 20
H18: · | T18: · | Y18: · | AI18: P4 2:25–3:25 개방형 항만 동진
H19: · | I19: · | J19: P5 | K19: · | L19: · | M19: 120 | N19: · | O19: · | P19: · | Q19: · | R19: · | S19: · | T19: · | Y19: ·
Y20: ·
Y21: · | AI21: P5 3:25–4:30 폭풍 방파제
Y22: · | Z22: · | AA22: · | AB22: · | AC22: S
AI24: S=시작 / E=다음 연결점 · 큰 코너 7개 · 작은 반복 지그재그 없음
A26: 구간 페이싱
A27: 단계 | B27: 시작(초) | C27: 종료(초) | D27: 구간시간 | E27: 표시 | F27: 동선 | G27: 전투 | H27: 주요 오브젝트 | I27: 휴식/보급 | J27: 종료 이벤트 | K27: 구현 상태
A28: P1 | B28: 0 | C28: 40 | D28: =C28-B28 -> 40 | E28: =TEXT(B28/86400,"m:ss")&"~"&TEXT(C28/86400,"m:ss") -> 0:00~0:40 | F28: 기존 하단→세로 부두 | G28: 방향 학습·소형 무리 | H28: 실측170: 수면98·시장바닥11·갈매기12·수조14·복어8 | I28: 없음 | J28: 상단 방향 전환 | K28: 현재씬 매칭 확장
A29: P2 | B29: 40 | C29: 90 | D29: =C29-B29 -> 50 | E29: =TEXT(B29/86400,"m:ss")&"~"&TEXT(C29/86400,"m:ss") -> 0:40~1:30 | F29: 상단 동쪽 경매 부두 | G29: 소형 무리 3회 | H29: 추가78: 시장파사드6·수조6·갈매기4·간트리1 | I29: 짧은 탄약 | J29: 첫 남쪽 턴 | K29: 현재씬 매칭 확장
A30: P3 | B30: 90 | C30: 145 | D30: =C30-B30 -> 55 | E30: =TEXT(B30/86400,"m:ss")&"~"&TEXT(C30/86400,"m:ss") -> 1:30~2:25 | F30: 냉동창고 역방향 | G30: 측면 압박 | H30: 추가90: 수면50·시장바닥6·어물6·복어3 | I30: 2:30 보급 | J30: 서쪽 긴 직선 | K30: 현재씬 매칭 확장
A31: P4 | B31: 145 | C31: 205 | D31: =C31-B31 -> 60 | E31: =TEXT(B31/86400,"m:ss")&"~"&TEXT(C31/86400,"m:ss") -> 2:25~3:25 | F31: 개방형 항만 동진 | G31: 개방 사격·엘리트 | H31: 추가84: 수면50·어선2·부표2·갈매기5 | I31: 턴 뒤 보급 | J31: 마지막 남쪽 턴 | K31: 현재씬 매칭 확장
A32: P5 | B32: 205 | C32: 270 | D32: =C32-B32 -> 65 | E32: =TEXT(B32/86400,"m:ss")&"~"&TEXT(C32/86400,"m:ss") -> 3:25~4:30 | F32: 폭풍 방파제 | G32: 압박 웨이브→보스 | H32: 추가89: 수면54·어물7·복어3·간트리1 | I32: 4:20 회복 | J32: 보스 부두 | K32: 현재씬 매칭 확장
A33: 합계 | D33: =SUM(D28:D32) -> 270 | E33: =TEXT(D33/86400,"m:ss") -> 4:30 | J33: 클리어 저장 → T1에서 다음 챕터 시작
A35: 검증: 71셀=142모듈(홀수 모듈은 마지막 셀에서 보정) · 긴 직선 8개 구간 · 큰 코너 7개 · 목표 4:30

Sheet 노량진_오브젝트매칭
A1: 노량진맵툴1 · 현재 씬 오브젝트 매칭 분석
A3: 열린 Noryangjin_MapTool_Mode의 저장 전(dirty) 계층을 읽기 전용으로 분석했습니다. Unity는 수정하지 않았고, 21도로·170오브젝트 패턴을 142모듈에 확장합니다.
A5: 현재 도로 21개 | D5: 현재 오브젝트 170개 | G5: 실측 프리팹 유형 16종 | J5: 확장 목표 142모듈 | M5: ="권장 총 인스턴스"&CHAR(10)&TEXT(N28,"0")&"개" -> 권장 총 인스턴스 511개
A9: 현재 씬 프리팹 실측 → 4:30 전체 구간 확장 수량
A11: 기호 | B11: 군 | C11: 실제 프리팹 ID | D11: 역할 | E11: 현재 | F11: 18u내 | G11: 우세 구간 | H11: 중앙거리 | I11: P1 현재 | J11: P2 추가 | K11: P3 추가 | L11: P4 추가 | M11: P5 추가 | N11: 전체 목표 | O11: 배율 | P11: 배치 규칙 | Q11: 프리팹 경로
A12: W | B12: 배경 | C12: 017_STAGE01_NRY_BG_001_Ocean_water_plane_backdrop | D12: 수면 연속 배경 | E12: 98 | F12: 17 | G12: 전 구간 | H12: 33 | I12: 98 | J12: 42 | K12: 50 | L12: 50 | M12: 54 | N12: =SUM(I12:M12) -> 294 | O12: =N12/E12 -> 3 | P12: 도로 외곽 전체를 10~15% 중첩 타일링 | Q12: Assets/ShooterSurvival/Prefabs/MeshyAI/Stage01_Noryangjin/017_STAGE01_NRY_BG_001_Ocean_water_plane_backdrop/017_STAGE01_NRY_BG_001_Ocean_water_plane_backdrop.prefab
A13: D | B13: 시장 | C13: 049_STAGE01_NRY_BG_033_Noryangjin_rainy_market_ground_backdrop | D13: 젖은 시장 지면 | E13: 11 | F13: 11 | G13: B 세로시장 | H13: 8.6 | I13: 11 | J13: 6 | K13: 6 | L13: 5 | M13: 4 | N13: =SUM(I13:M13) -> 32 | O13: =N13/E13 -> 2.9090909 | P13: 시장 클러스터 아래만 연속, 통로 중앙 제외 | Q13: Assets/ShooterSurvival/Prefabs/MeshyAI/Stage01_Noryangjin/049_STAGE01_NRY_BG_033_Noryangjin_rainy_market_ground_backdrop/049_STAGE01_NRY_BG_033_Noryangjin_rainy_market_ground_backdrop.prefab
A14: S | B14: 항만 | C14: 008_STAGE01_NRY_PROPS_008_Seagull_perch_post | D14: 갈매기 횃대 기둥 | E14: 12 | F14: 12 | G14: B 세로시장 | H14: 6.8 | I14: 12 | J14: 4 | K14: 5 | L14: 5 | M14: 6 | N14: =SUM(I14:M14) -> 32 | O14: =N14/E14 -> 2.6666667 | P14: 바깥 난간 2~4개 묶음, 3~4셀 간격 | Q14: Assets/ShooterSurvival/Prefabs/MeshyAI/Stage01_Noryangjin/008_STAGE01_NRY_PROPS_008_Seagull_perch_post/008_STAGE01_NRY_PROPS_008_Seagull_perch_post.prefab
A15: P | B15: 위협 | C15: 010_STAGE01_NRY_ENEMY_010_Puffer_enemy | D15: 복어 적/위협 표식 | E15: 8 | F15: 7 | G15: 전 구간 | H15: 9.3 | I15: 8 | J15: 2 | K15: 3 | L15: 2 | M15: 3 | N15: =SUM(I15:M15) -> 18 | O15: =N15/E15 -> 2.25 | P15: 직선 중반에 2~3개, 턴 전후 2셀 금지 | Q15: Assets/ShooterSurvival/Prefabs/MeshyAI/Stage01_Noryangjin/010_STAGE01_NRY_ENEMY_010_Puffer_enemy/010_STAGE01_NRY_ENEMY_010_Puffer_enemy.prefab
A16: Qc | B16: 시장 | C16: 030_STAGE01_NRY_PROPS_019_Crab_aquarium_tank | D16: 게 수조 | E16: 7 | F16: 7 | G16: B 세로시장 | H16: 3 | I16: 7 | J16: 3 | K16: 3 | L16: 2 | M16: 1 | N16: =SUM(I16:M16) -> 16 | O16: =N16/E16 -> 2.2857143 | P16: 문어 수조와 교대, 파사드 반대쪽 | Q16: Assets/ShooterSurvival/Prefabs/MeshyAI/Stage01_Noryangjin/030_STAGE01_NRY_PROPS_019_Crab_aquarium_tank/030_STAGE01_NRY_PROPS_019_Crab_aquarium_tank.prefab
A17: Qo | B17: 시장 | C17: 031_STAGE01_NRY_PROPS_020_Octopus_aquarium_tank | D17: 문어 수조 | E17: 7 | F17: 7 | G17: B 세로시장 | H17: 9 | I17: 7 | J17: 3 | K17: 3 | L17: 2 | M17: 1 | N17: =SUM(I17:M17) -> 16 | O17: =N17/E17 -> 2.2857143 | P17: 게 수조와 교대, 한 셀 건너 배치 | Q17: Assets/ShooterSurvival/Prefabs/MeshyAI/Stage01_Noryangjin/031_STAGE01_NRY_PROPS_020_Octopus_aquarium_tank/031_STAGE01_NRY_PROPS_020_Octopus_aquarium_tank.prefab
A18: F | B18: 바닥 | C18: 040_STAGE01_NRY_DCR_030_Fish_scrap_floor_scatter | D18: 어물 바닥 산개 | E18: 13 | F18: 10 | G18: 전 구간 | H18: 10.5 | I18: 13 | J18: 5 | K18: 6 | L18: 5 | M18: 7 | N18: =SUM(I18:M18) -> 36 | O18: =N18/E18 -> 2.7692308 | P18: 가장자리 3~5개 묶음, 중앙 사격축 비움 | Q18: Assets/ShooterSurvival/Prefabs/MeshyAI/Stage01_Noryangjin/040_STAGE01_NRY_DCR_030_Fish_scrap_floor_scatter/040_STAGE01_NRY_DCR_030_Fish_scrap_floor_scatter.prefab
A19: L | B19: 항만 | C19: 024_STAGE01_NRY_PROPS_012_Life_ring_buoy | D19: 구명환 | E19: 3 | F19: 3 | G19: B 세로시장 | H19: 9 | I19: 3 | J19: 2 | K19: 2 | L19: 2 | M19: 3 | N19: =SUM(I19:M19) -> 12 | O19: =N19/E19 -> 4 | P19: 난간·횃대에 부착, 8~12셀 간격 | Q19: Assets/ShooterSurvival/Prefabs/MeshyAI/Stage01_Noryangjin/024_STAGE01_NRY_PROPS_012_Life_ring_buoy/024_STAGE01_NRY_PROPS_012_Life_ring_buoy.prefab
A20: M1 | B20: 시장 | C20: 014_STAGE01_NRY_BLD_001_Fish_market_storefront_facade | D20: 수산시장 파사드 | E20: 2 | F20: 2 | G20: B 세로시장 | H20: 10.4 | I20: 2 | J20: 2 | K20: 2 | L20: 1 | M20: 1 | N20: =SUM(I20:M20) -> 8 | O20: =N20/E20 -> 4 | P20: 시장 구간 한쪽 면에만 2개씩 묶음 | Q20: Assets/ShooterSurvival/Prefabs/MeshyAI/Stage01_Noryangjin/014_STAGE01_NRY_BLD_001_Fish_market_storefront_facade/014_STAGE01_NRY_BLD_001_Fish_market_storefront_facade.prefab
A21: M2 | B21: 시장 | C21: 015_STAGE01_NRY_BLD_002_Sashimi_restaurant_stall_front | D21: 횟집 매대 | E21: 2 | F21: 2 | G21: B 세로시장 | H21: 10.2 | I21: 2 | J21: 2 | K21: 2 | L21: 1 | M21: 1 | N21: =SUM(I21:M21) -> 8 | O21: =N21/E21 -> 4 | P21: M1-M2-M3 순환, 반대편 5u 확보 | Q21: Assets/ShooterSurvival/Prefabs/MeshyAI/Stage01_Noryangjin/015_STAGE01_NRY_BLD_002_Sashimi_restaurant_stall_front/015_STAGE01_NRY_BLD_002_Sashimi_restaurant_stall_front.prefab
A22: M3 | B22: 시장 | C22: 016_STAGE01_NRY_BLD_003_Seafood_display_stall_module | D22: 해산물 진열 매대 | E22: 2 | F22: 2 | G22: B 세로시장 | H22: 10.2 | I22: 2 | J22: 2 | K22: 2 | L22: 2 | M22: 0 | N22: =SUM(I22:M22) -> 8 | O22: =N22/E22 -> 4 | P22: 수조 앞 1셀 여백, 코너 진입부 금지 | Q22: Assets/ShooterSurvival/Prefabs/MeshyAI/Stage01_Noryangjin/016_STAGE01_NRY_BLD_003_Seafood_display_stall_module/016_STAGE01_NRY_BLD_003_Seafood_display_stall_module.prefab
A23: A | B23: 항만 | C23: 035_STAGE01_NRY_PROPS_024_Anchor_prop | D23: 닻 | E23: 1 | F23: 1 | G23: B 세로시장 | H23: 7.3 | I23: 1 | J23: 1 | K23: 1 | L23: 1 | M23: 2 | N23: =SUM(I23:M23) -> 6 | O23: =N23/E23 -> 6 | P23: 큰 코너 출구 바깥쪽에 1개 | Q23: Assets/ShooterSurvival/Prefabs/MeshyAI/Stage01_Noryangjin/035_STAGE01_NRY_PROPS_024_Anchor_prop/035_STAGE01_NRY_PROPS_024_Anchor_prop.prefab
... A27: BY | B27: 항만 | C27: 037_STAGE01_NRY_BG_026_Floating_sea_buoy | D27: 해상 부표 | E27: 1 | F27: 1 | G27: A 하단진입 | H27: 14.9 | I27: 1 | J27: 2 | K27: 2 | L27: 2 | M27: 3 | N27: =SUM(I27:M27) -> 10 | O27: =N27/E27 -> 10 | P27: 어선 조망 앞 바깥 수면에 2~3개 | Q27: Assets/ShooterSurvival/Prefabs/MeshyAI/Stage01_Noryangjin/037_STAGE01_NRY_BG_026_Floating_sea_buoy/037_STAGE01_NRY_BG_026_Floating_sea_buoy.prefab
A28: 합계 | E28: =SUM(E12:E27) -> 170 | F28: =SUM(F12:F27) -> 84 | G28: — | H28: =SUMPRODUCT(E12:E27,H12:H27)/SUM(E12:E27) -> 23.104706 | I28: =SUM(I12:I27) -> 170 | J28: =SUM(J12:J27) -> 78 | K28: =SUM(K12:K27) -> 90 | L28: =SUM(L12:L27) -> 84 | M28: =SUM(M12:M27) -> 89 | N28: =SUM(N12:N27) -> 511 | O28: =N28/E28 -> 3.0058824 | P28: 현재 170개 + 추가 341개 = 511개. 수면은 길이 비례가 아니라 꺾인 동선의 피복 면적으로 3배만 확장 | Q28: Source: active Noryangjin_MapTool_Mode hierarchy, read-only, 2026-07-19
A31: 현재 21도로의 공간 매칭
A33: 구역 | C33: 도로 | E33: 실측 오브젝트 구성 | J33: 읽힌 패턴 | N33: 142모듈 적용
A34: A 하단 진입부 | C34: 4개 | E34: 수면51·어물5·복어3·부표1·갈매기1 | J34: 바다 조망 + 낮은 바닥 디테일, 적은 직선 중반 | N34: P1 시작과 P4 개방 항만에 BT-BY-F-P 조합
A35: B 세로 수산시장 | C35: 9개 | E35: 수조14·파사드6·갈매기7·시장바닥7·구명환3 | J35: 파사드 한쪽 + 수조 반대쪽, 중앙 통로 비움 | N35: P2·P3에 M1/M2/M3-Qc/Qo 교대 반복
A36: C 상단 출구부 | C36: 8개 | E36: 수면19·시장바닥4·갈매기4·어물4·복어2 | J36: 시장 밀도를 낮추며 항만으로 전환 | N36: P3 출구와 P5 방파제에 S-F-P 완만 전환
A39: 오브젝트 매치 세트
A41: 세트 | C41: 조합 | E41: 배치 순서 | J41: 간격/금지 | N41: 목적
A42: 시장 M-Q | C42: M1/M2/M3 + Qc/Qo + D | E42: 파사드 → 1셀 → 수조 교대 | J42: 반대편 5u 확보·턴 ±2셀 금지 | N42: 수산시장 정체성 + 전투 시야
A43: 항만 BT-BY-L | C43: BT + BY + L + S | E43: 어선 조망 → 부표 → 구명환/횃대 | J43: 4셀 이상 직선 바깥쪽 | N43: 개방 수면과 안전 난간 리듬
A44: 바닥 F-S | C44: F + S | E44: 어물 산개 뒤 1~2셀에 갈매기 | J44: 중앙축 금지·가장자리만 | N44: 낮은 디테일로 속도감 유지
A45: 위협 G-P | C45: G + P | E45: 간트리 통과 → 2셀 뒤 복어 | J45: 코너·회복 포켓과 분리 | N45: 페이즈 전환을 읽히게 함
A46: 배경 W-V | C46: W + V | E46: 수면 연속 → 원경 마을 | J46: V는 진행축 40u 이상 | N46: 길을 막지 않는 깊이감

Sheet 노량진_오브젝트배치
A1: 노량진 4:30 · 현재 오브젝트 매치 확장 배치도
A3: 초록 11셀은 현재 21도로 실측 구간입니다. 붉은 확장 구간에는 시장(M/Q)·항만(BT/BY/L/S)·바닥(F)·위협(G/P) 조합을 실제 씬 밀도보다 완화해 배치합니다.
A5: 현재 실측 21도로 / 170오브젝트 | H5: 전체 목표 142모듈 / 4:30 | O5: ="권장 인스턴스"&CHAR(10)&TEXT(노량진_오브젝트매칭!N28,"0")&"개" -> 권장 인스턴스 511개 | V5: 중앙 확보 최소 5u | AC5: 배치 원칙 턴 ±2셀 대형물 금지
AI9: 기호 범례
L10: BY | O10: A | S10: M | W10: P | AA10: Q | AD10: BT
G11: F | H11: · | I11: · | J11: · | K11: · | L11: · | M11: · | N11: P4 | O11: · | P11: · | Q11: · | R11: · | S11: · | T11: · | U11: · | V11: · | W11: · | X11: 60 | Y11: · | Z11: · | AA11: · | AB11: · | AC11: P3 | AD11: · | AE11: · | AI11: M | AK11: 시장 파사드 | AN11: M1/M2/M3
H12: · | J12: S | N12: BT | Q12: Q | U12: S | Y12: F | AC12: M | AD12: S | AE12: · | AI12: Q | AK12: 수조 | AN12: Qc/Qo 교대
H13: · | I13: P | AE13: · | AI13: S | AK13: 갈매기 횃대 | AN13: 2~4개
H14: · | AE14: 40 | AF14: G | AI14: F | AK14: 어물 바닥 | AN14: 3~5개
G15: BT | H15: 100 | AD15: P | AE15: · | AI15: P | AK15: 복어 위협 | AN15: 2~3개
H16: · | T16: T1 | Z16: S | AB16: Q | AE16: · | AF16: Q | AI16: G | AK16: 신호 간트리 | AN16: 1개
H17: · | I17: L | S17: P | T17: 140 | X17: V | Y17: 21 | Z17: P2 | AA17: · | AB17: · | AC17: · | AD17: · | AE17: · | AF17: M | AI17: BT | AK17: 어선 조망 | AN17: 1개
H18: · | T18: · | X18: L | Y18: 20 | AA18: M | AC18: F | AI18: BY | AK18: 부표 | AN18: 2~3개
G19: A | H19: · | K19: F | O19: BY | S19: V | T19: · | U19: G | Y19: · | Z19: Q | AI19: L | AK19: 구명환 | AN19: 2~3개
G20: G | H20: · | I20: P5 | J20: · | K20: · | L20: · | M20: 120 | N20: · | O20: · | P20: · | Q20: · | R20: · | S20: · | T20: · | X20: M | Y20: · | AI20: A | AK20: 닻 | AN20: 1개
I21: S | M21: P | Q21: BT | Y21: · | Z21: Q | AI21: V | AK21: 원경 마을 | AN21: 1개
X22: M | Y22: · | AA22: P | AC22: G | AI22: W/D | AK22: 수면/시장지면 | AN22: 연속 피복
X23: S | Y23: · | Z23: · | AA23: · | AB23: · | AC23: S
Z24: F | AB24: BY
A27: 페이즈별 실제 매칭 확장
A29: 단계 | D29: 표시셀 | G29: 모듈 | J29: 시간 | M29: 인스턴스 | Q29: 주요 매치 | Z29: 배치 의도
A30: P1 현재 | D30: 1~11 | G30: 21 | J30: 0:00~0:40 | M30: =노량진_오브젝트매칭!I28 -> 170 | Q30: 실측 G-BY-P-F-S-M-Q-L-V | Z30: 현재 열린 씬 21도로·170개를 그대로 기준점으로 사용
A31: P2 | D31: 12~24 | G31: 26 | J31: 0:40~1:30 | M31: =노량진_오브젝트매칭!J28 -> 78 | Q31: M-Q-S-F-G | Z31: 시장 파사드 한쪽, 수조 반대쪽, 중앙 5u 확보
A32: P3 | D32: 25~39 | G32: 30 | J32: 1:30~2:25 | M32: =노량진_오브젝트매칭!K28 -> 90 | Q32: M-Q-F-P-G | Z32: 냉동창고 역방향, 간트리 2셀 뒤 복어
A33: P4 | D33: 40~55 | G33: 32 | J33: 2:25~3:25 | M33: =노량진_오브젝트매칭!L28 -> 84 | Q33: BT-BY-S-F-P-L-A | Z33: 개방 항만 바깥 수면에 어선·부표 조망
A34: P5 | D34: 56~71 | G34: 33 | J34: 3:25~4:30 | M34: =노량진_오브젝트매칭!M28 -> 89 | Q34: S-F-P-BY-BT-V-G | Z34: 방파제 압박, 보스 사격축·회복 포켓은 비움
A37: 배치 판정: 현재 씬의 170개를 단순 6.76배 복제하면 1,149개가 되어 길이보다 오브젝트가 먼저 읽힙니다. 수면은 피복 면적 기준 3배, 전경 소품은 1.5~3배로 완화해 총 511개를 권장합니다. 지도 기호는 클러스터 위치이며 정확 수량은 매칭 시트의 P1~P5 열이 기준입니다.
A41: Unity 적용 시 주의: 이 Excel은 설계안입니다. 현재 Noryangjin_MapTool_Mode는 dirty 상태이며 수정하지 않았습니다. 실제 배치는 프리팹 루트 변환을 유지하고, 턴 전후 2셀·중앙 5u·보급 포켓을 비운 뒤 별도 검증해야 합니다.

Sheet 02_고속도로_4분
A1: CH.2 고속도로 · 4:00 직선·꺾임 축척 맵
A2: 노량진 T1과 같은 점에서 시작합니다. 상행 장거리→좌측 장거리→합류 직선의 3코너 구조라 고속도로답게 오래 뻗습니다.
B4: 목표시간 | I4: 구현 상태 | P4: 동선 구조 | X4: 피날레
B5: 4:00 | I5: 기존 씬 기반 제안 | P5: 최장 직선 25셀 · 코너 간 평균 60초 | X5: 터널·대형 차량 매복
B7: 다이나믹 축척 1셀=2모듈 | J7: 상행 장거리 · 좌측 장거리 · 합류 직선 | T7: 125모듈 · 63셀 · 큰 코너 3개 | AI7: 단계 색상·시간
AI9: P1 0:00–0:40 직선 본선
D10: P4 | E10: · | F10: · | G10: · | H10: · | I10: · | J10: · | K10: · | L10: 60 | M10: · | N10: · | O10: · | P10: P3 | Q10: · | R10: · | S10: · | T10: · | U10: · | V10: 40 | W10: · | X10: · | Y10: · | Z10: · | AA10: · | AB10: · | AC10: P2
D11: · | AC11: ·
D12: 80 | AC12: · | AI12: P2 0:40–1:25 고가 커브 램프
D13: · | AC13: 20
D14: · | AC14: ·
D15: · | E15: · | F15: · | G15: · | H15: · | I15: · | J15: · | K15: 100 | L15: P5 | M15: · | N15: · | O15: · | P15: · | Q15: · | R15: · | S15: · | T15: · | U15: 120 | V15: · | W15: · | X15: E | AC15: · | AI15: P3 1:25–2:10 Y분기·차선 합류
AC16: ·
AC17: ·
AC18: · | AI18: P4 2:10–3:05 톨게이트 접근
AC19: ·
AC20: ·
AC21: · | AI21: P5 3:05–4:00 터널·고가도로
AC22: S
AI24: S=시작 / E=다음 연결점 · 큰 코너 3개 · 작은 반복 지그재그 없음
A26: 구간 페이싱
A27: 단계 | B27: 시작(초) | C27: 종료(초) | D27: 구간시간 | E27: 표시 | F27: 동선 | G27: 전투 | H27: 주요 오브젝트 | I27: 휴식/보급 | J27: 종료 이벤트 | K27: 구현 상태
A28: P1 | B28: 0 | C28: 40 | D28: =C28-B28 -> 40 | E28: =TEXT(B28/86400,"m:ss")&"~"&TEXT(C28/86400,"m:ss") -> 0:00~0:40 | F28: 직선 본선 | G28: 차선 학습·소형 적 | H28: 가드레일·표지판 | I28: 없음 | J28: 속도감 확보 | K28: 기존 씬 기반 제안
A29: P2 | B29: 40 | C29: 85 | D29: =C29-B29 -> 45 | E29: =TEXT(B29/86400,"m:ss")&"~"&TEXT(C29/86400,"m:ss") -> 0:40~1:25 | F29: 고가 커브 램프 | G29: 코너 압박 | H29: 셰브론·방음벽 | I29: 짧은 탄약 | J29: 램프 하강 | K29: 기존 씬 기반 제안
A30: P3 | B30: 85 | C30: 130 | D30: =C30-B30 -> 45 | E30: =TEXT(B30/86400,"m:ss")&"~"&TEXT(C30/86400,"m:ss") -> 1:25~2:10 | F30: Y분기·차선 합류 | G30: 차량 사이 전투 | H30: 승용차·트럭·드럼통 | I30: 2:30 보급 | J30: 선택 차선 합류 | K30: 기존 씬 기반 제안
A31: P4 | B31: 130 | C31: 185 | D31: =C31-B31 -> 55 | E31: =TEXT(B31/86400,"m:ss")&"~"&TEXT(C31/86400,"m:ss") -> 2:10~3:05 | F31: 톨게이트 접근 | G31: 차단봉·게이트 웨이브 | H31: 톨부스·신호등 | I31: 통과 직후 회복 | J31: 전자 톨게이트 | K31: 기존 씬 기반 제안
A32: P5 | B32: 185 | C32: 240 | D32: =C32-B32 -> 55 | E32: =TEXT(B32/86400,"m:ss")&"~"&TEXT(C32/86400,"m:ss") -> 3:05~4:00 | F32: 터널·고가도로 | G32: 버스·트럭 매복 | H32: 터널·속도카메라 | I32: 3:45 탄약 | J32: 터널 출구 보스 | K32: 기존 씬 기반 제안
A33: 합계 | D33: =SUM(D28:D32) -> 240 | E33: =TEXT(D33/86400,"m:ss") -> 4:00 | J33: 클리어 저장 → T2에서 다음 챕터 시작
A35: 검증: 63셀=125모듈(홀수 모듈은 마지막 셀에서 보정) · 긴 직선 4개 구간 · 큰 코너 3개 · 목표 4:00

Sheet 03_휴게소_2분
A1: CH.3 휴게소 · 2:00 직선·꺾임 축척 맵
A2: 2분 완충 구간입니다. 진입·주차 회차·출구에만 4개의 큰 코너를 두고 짧은 지그재그는 넣지 않습니다.
B4: 목표시간 | I4: 구현 상태 | P4: 동선 구조 | X4: 피날레
B5: 2:00 | I5: 문서 기반 신규 제안 | P5: 최장 직선 9셀 · 코너 간 평균 24초 | X5: 출구 30초 방어
B7: 다이나믹 축척 1셀=2모듈 | J7: 진입 직선 · 주차 회차 · 출구 직선 | T7: 61모듈 · 31셀 · 큰 코너 4개 | AI7: 단계 색상·시간
AI9: P1 0:00–0:25 서비스 도로 진입
AB10: E | AC10: 60 | AD10: ·
AD11: ·
AD12: · | AI12: P2 0:25–0:55 편의점·푸드 구역
AD13: ·
U14: P3 | V14: · | W14: · | X14: · | Y14: 40 | Z14: · | AA14: · | AB14: P4 | AC14: · | AD14: ·
U15: · | AI15: P3 0:55–1:30 주차장 루프
U16: ·
U17: ·
U18: · | AI18: P4 1:30–2:00 주유소 출구
U19: ·
U20: 20
U21: P2 | V21: · | W21: · | X21: · | Y21: · | Z21: · | AA21: · | AB21: · | AC21: S
AI24: S=시작 / E=다음 연결점 · 큰 코너 4개 · 작은 반복 지그재그 없음
A26: 구간 페이싱
A27: 단계 | B27: 시작(초) | C27: 종료(초) | D27: 구간시간 | E27: 표시 | F27: 동선 | G27: 전투 | H27: 주요 오브젝트 | I27: 휴식/보급 | J27: 종료 이벤트 | K27: 구현 상태
A28: P1 | B28: 0 | C28: 25 | D28: =C28-B28 -> 25 | E28: =TEXT(B28/86400,"m:ss")&"~"&TEXT(C28/86400,"m:ss") -> 0:00~0:25 | F28: 서비스 도로 진입 | G28: 저강도 정리 | H28: 휴게소 간판·볼라드 | I28: 회복 드롭 | J28: 건물 앞 진입 | K28: 문서 기반 신규 제안
A29: P2 | B29: 25 | C29: 55 | D29: =C29-B29 -> 30 | E29: =TEXT(B29/86400,"m:ss")&"~"&TEXT(C29/86400,"m:ss") -> 0:25~0:55 | F29: 편의점·푸드 구역 | G29: 전투 최소 | H29: 자판기·푸드부스 | I29: 상점·회복 | J29: 선택 구매 | K29: 문서 기반 신규 제안
A30: P3 | B30: 55 | C30: 90 | D30: =C30-B30 -> 35 | E30: =TEXT(B30/86400,"m:ss")&"~"&TEXT(C30/86400,"m:ss") -> 0:55~1:30 | F30: 주차장 루프 | G30: 차량 사이 소형 웨이브 | H30: SUV·셔틀버스 | I30: 탄약 포켓 | J30: 출구로 복귀 | K30: 문서 기반 신규 제안
A31: P4 | B31: 90 | C31: 120 | D31: =C31-B31 -> 30 | E31: =TEXT(B31/86400,"m:ss")&"~"&TEXT(C31/86400,"m:ss") -> 1:30~2:00 | F31: 주유소 출구 | G31: 30초 방어 | H31: 주유기·캐노피 | I31: 클리어 회복 | J31: 도심 해금 | K31: 문서 기반 신규 제안
A32: 합계 | D32: =SUM(D28:D31) -> 120 | E32: =TEXT(D32/86400,"m:ss") -> 2:00 | J32: 클리어 저장 → T3에서 다음 챕터 시작
A34: 검증: 31셀=61모듈(홀수 모듈은 마지막 셀에서 보정) · 긴 직선 5개 구간 · 큰 코너 4개 · 목표 2:00

Sheet 04_도심_4분30초
A1: CH.4 도심 · 4:30 직선·꺾임 축척 맵
A2: 긴 대로 사이에 큰 교차로와 공사 우회를 배치합니다. 8개 코너가 약 30초 간격으로 공간 리듬을 바꿉니다.
B4: 목표시간 | I4: 구현 상태 | P4: 동선 구조 | X4: 피날레
B5: 4:30 | I5: 문서 기반 신규 제안 | P5: 최장 직선 24셀 · 코너 간 평균 45초 | X5: 대형 교차로 엘리트전
B7: 다이나믹 축척 1셀=2모듈 | J7: 긴 대로 · 큰 교차로 · 공사 우회 | T7: 141모듈 · 71셀 · 큰 코너 5개 | AI7: 단계 색상·시간
AI9: P1 0:00–0:45 횡단보도 직선
E10: · | F10: · | G10: · | H10: · | I10: · | J10: · | K10: 60 | L10: P3 | M10: · | N10: · | O10: · | P10: · | Q10: · | R10: · | S10: · | T10: · | U10: 40 | V10: · | W10: · | X10: · | Y10: · | Z10: P2 | AA10: · | AB10: · | AC10: ·
E11: · | AC11: ·
E12: · | AC12: 20 | AI12: P2 0:45–1:35 지하철 S커브
E13: · | AC13: ·
E14: 80 | AC14: ·
E15: · | AC15: · | AI15: P3 1:35–2:30 T자 대형 교차로
E16: · | F16: P4 | G16: · | H16: · | I16: · | J16: · | K16: · | L16: · | M16: 100 | N16: · | O16: · | P16: · | Q16: · | R16: · | S16: · | T16: P5 | U16: · | V16: · | W16: 120 | X16: · | AC16: ·
X17: · | AC17: ·
X18: · | AC18: · | AI18: P4 2:30–3:30 공사 밀집 거리
X19: · | AC19: ·
X20: · | AC20: ·
X21: · | AC21: S | AI21: P5 3:30–4:30 도심 출구
T22: E | U22: 140 | V22: · | W22: · | X22: ·
AI24: S=시작 / E=다음 연결점 · 큰 코너 5개 · 작은 반복 지그재그 없음
A26: 구간 페이싱
A27: 단계 | B27: 시작(초) | C27: 종료(초) | D27: 구간시간 | E27: 표시 | F27: 동선 | G27: 전투 | H27: 주요 오브젝트 | I27: 휴식/보급 | J27: 종료 이벤트 | K27: 구현 상태
A28: P1 | B28: 0 | C28: 45 | D28: =C28-B28 -> 45 | E28: =TEXT(B28/86400,"m:ss")&"~"&TEXT(C28/86400,"m:ss") -> 0:00~0:45 | F28: 횡단보도 직선 | G28: 택시 사이 소형 웨이브 | H28: 버스정류장·가로수 | I28: 없음 | J28: 첫 교차로 | K28: 문서 기반 신규 제안
A29: P2 | B29: 45 | C29: 95 | D29: =C29-B29 -> 50 | E29: =TEXT(B29/86400,"m:ss")&"~"&TEXT(C29/86400,"m:ss") -> 0:45~1:35 | F29: 지하철 S커브 | G29: 측면 적·스쿠터 | H29: 지하철 입구·광고판 | I29: 짧은 탄약 | J29: 90도 코너 | K29: 문서 기반 신규 제안
A30: P3 | B30: 95 | C30: 150 | D30: =C30-B30 -> 55 | E30: =TEXT(B30/86400,"m:ss")&"~"&TEXT(C30/86400,"m:ss") -> 1:35~2:30 | F30: T자 대형 교차로 | G30: 사방 진입 웨이브 | H30: 신호등·상가 파사드 | I30: 2:30 보급 | J30: 교차로 선택 | K30: 문서 기반 신규 제안
A31: P4 | B31: 150 | C31: 210 | D31: =C31-B31 -> 60 | E31: =TEXT(B31/86400,"m:ss")&"~"&TEXT(C31/86400,"m:ss") -> 2:30~3:30 | F31: 공사 밀집 거리 | G31: 엘리트·좁은 차선 | H31: 펜스·비계·콘 | I31: 공사 뒤 회복 | J31: 버스전용차로 | K31: 문서 기반 신규 제안
A32: P5 | B32: 210 | C32: 270 | D32: =C32-B32 -> 60 | E32: =TEXT(B32/86400,"m:ss")&"~"&TEXT(C32/86400,"m:ss") -> 3:30~4:30 | F32: 도심 출구 | G32: 대형 교차로 엘리트 | H32: 버스·택시·배너 | I32: 4:15 탄약 | J32: 강남 전환 게이트 | K32: 문서 기반 신규 제안
A33: 합계 | D33: =SUM(D28:D32) -> 270 | E33: =TEXT(D33/86400,"m:ss") -> 4:30 | J33: 클리어 저장 → T4에서 다음 챕터 시작
A35: 검증: 71셀=141모듈(홀수 모듈은 마지막 셀에서 보정) · 긴 직선 6개 구간 · 큰 코너 5개 · 목표 4:30

Sheet 05_백화점_5분
A1: CH.5 백화점 · 5:00 직선·꺾임 축척 맵
A2: 명품대로 직선, 발렛 진입, 정문 접근을 8개의 큰 코너로 연결합니다. 최종 5분 길이를 그대로 유지합니다.
B4: 목표시간 | I4: 구현 상태 | P4: 동선 구조 | X4: 피날레
B5: 5:00 | I5: 문서 기반 신규 제안 | P5: 최장 직선 24셀 · 코너 간 평균 50초 | X5: 백화점 입구 최종 보스
B7: 다이나믹 축척 1셀=2모듈 | J7: 명품대로 · 발렛 꺾임 · 정문 진입 | T7: 157모듈 · 79셀 · 큰 코너 5개 | AI7: 단계 색상·시간
AI9: P1 0:00–0:45 명품거리 직선
E10: · | F10: · | G10: · | H10: · | I10: P3 | J10: · | K10: 60 | L10: · | M10: · | N10: · | O10: · | P10: · | Q10: · | R10: · | S10: · | T10: · | U10: 40 | V10: · | W10: · | X10: P2 | Y10: · | Z10: · | AA10: · | AB10: · | AC10: ·
E11: · | AC11: ·
E12: · | AC12: 20 | AI12: P2 0:45–1:40 부티크 S커브
E13: · | AC13: ·
E14: 80 | AC14: ·
E15: · | AC15: · | AI15: P3 1:40–2:45 백화점 광장 분기
E16: · | F16: · | G16: · | H16: · | I16: · | J16: · | K16: P4 | L16: · | M16: 100 | N16: · | O16: · | P16: · | Q16: · | R16: · | S16: · | T16: · | U16: · | V16: · | W16: 120 | X16: · | Y16: · | AC16: ·
Y17: P5 | AC17: ·
Y18: · | AC18: · | AI18: P4 2:45–3:50 발렛 헤어핀
Y19: · | AC19: ·
Y20: · | AC20: ·
Y21: · | AC21: S | AI21: P5 3:50–5:00 백화점 입구
N22: E | O22: · | P22: · | Q22: · | R22: · | S22: · | T22: · | U22: · | V22: · | W22: 140 | X22: · | Y22: ·
AI24: S=시작 / E=다음 연결점 · 큰 코너 5개 · 작은 반복 지그재그 없음
A26: 구간 페이싱
A27: 단계 | B27: 시작(초) | C27: 종료(초) | D27: 구간시간 | E27: 표시 | F27: 동선 | G27: 전투 | H27: 주요 오브젝트 | I27: 휴식/보급 | J27: 종료 이벤트 | K27: 구현 상태
A28: P1 | B28: 0 | C28: 45 | D28: =C28-B28 -> 45 | E28: =TEXT(B28/86400,"m:ss")&"~"&TEXT(C28/86400,"m:ss") -> 0:00~0:45 | F28: 명품거리 직선 | G28: 정예 소형 웨이브 | H28: 쇼윈도·배너 기둥 | I28: 없음 | J28: 부티크 S커브 | K28: 문서 기반 신규 제안
A29: P2 | B29: 45 | C29: 100 | D29: =C29-B29 -> 55 | E29: =TEXT(B29/86400,"m:ss")&"~"&TEXT(C29/86400,"m:ss") -> 0:45~1:40 | F29: 부티크 S커브 | G29: 볼라드 사이 압박 | H29: 마네킹·진열대 | I29: 짧은 탄약 | J29: 광장 진입 | K29: 문서 기반 신규 제안
A30: P3 | B30: 100 | C30: 165 | D30: =C30-B30 -> 65 | E30: =TEXT(B30/86400,"m:ss")&"~"&TEXT(C30/86400,"m:ss") -> 1:40~2:45 | F30: 백화점 광장 분기 | G30: 개방형 정예전 | H30: LED 패널·조형물 | I30: 2:30 보급 | J30: 발렛 루프 | K30: 문서 기반 신규 제안
A31: P4 | B31: 165 | C31: 230 | D31: =C31-B31 -> 65 | E31: =TEXT(B31/86400,"m:ss")&"~"&TEXT(C31/86400,"m:ss") -> 2:45~3:50 | F31: 발렛 헤어핀 | G31: 검은 세단·미니보스 | H31: 발렛부스·로프 | I31: 루프 뒤 회복 | J31: 정문 수렴 | K31: 문서 기반 신규 제안
A32: P5 | B32: 230 | C32: 300 | D32: =C32-B32 -> 70 | E32: =TEXT(B32/86400,"m:ss")&"~"&TEXT(C32/86400,"m:ss") -> 3:50~5:00 | F32: 백화점 입구 | G32: 최종 보스 | H32: 자동문·다이아 조형물 | I32: 4:40 최종 보급 | J32: 최종 보상 | K32: 문서 기반 신규 제안
A33: 합계 | D33: =SUM(D28:D32) -> 300 | E33: =TEXT(D33/86400,"m:ss") -> 5:00 | J33: 최종 클리어 저장 → 캠페인 완료
A35: 검증: 79셀=157모듈(홀수 모듈은 마지막 셀에서 보정) · 긴 직선 6개 구간 · 큰 코너 5개 · 목표 5:00

Sheet 구간_오브젝트표
A1: 5개 챕터 구간·오브젝트 배치표 · 노량진 현재씬 매칭 반영
A2: 노량진은 현재 열린 맵툴 씬의 21도로·170개 오브젝트를 기준으로 확장했습니다. 중앙 통로와 턴 전후 2셀은 계속 비웁니다.
A4: ID | B4: 챕터 | C4: 단계 | D4: 시간 | E4: 동선 | F4: 전투 | G4: 주요 오브젝트 | H4: 휴식/보급 | I4: 피날레 | J4: 중앙 확보폭 | K4: 구현 상태 | L4: 배치 주의
A5: NRY-01 | B5: 노량진 | C5: P1 | D5: 0:00~0:40 | E5: 기존 하단→세로 부두 | F5: 방향 학습·소형 무리 | G5: 실측170: W98·D11·S12·Q14·P8 | H5: 없음 | I5: 상단 방향 전환 | J5: 5u | K5: 현재씬 매칭 | L5: 열린 씬 21도로·170개 그대로 기준
A6: NRY-02 | B6: 노량진 | C6: P2 | D6: 0:40~1:30 | E6: 상단 동쪽 경매 부두 | F6: 소형 무리 3회 | G6: 추가78: M6·Q6·S4·F5·G1 | H6: 짧은 탄약 | I6: 첫 남쪽 턴 | J6: 5u | K6: 현재씬 매칭 확장 | L6: M-Q 교대, 턴 ±2셀 대형물 금지
A7: NRY-03 | B7: 노량진 | C7: P3 | D7: 1:30~2:25 | E7: 냉동창고 역방향 | F7: 측면 압박 | G7: 추가90: W50·D6·F6·P3·G1 | H7: 2:30 보급 | I7: 서쪽 긴 직선 | J7: 5u | K7: 현재씬 매칭 확장 | L7: 간트리 뒤 2셀부터 복어 배치
A8: NRY-04 | B8: 노량진 | C8: P4 | D8: 2:25~3:25 | E8: 개방형 항만 동진 | F8: 개방 사격·엘리트 | G8: 추가84: W50·BT2·BY2·S5 | H8: 턴 뒤 보급 | I8: 마지막 남쪽 턴 | J8: 5u | K8: 현재씬 매칭 확장 | L8: 수면 바깥쪽 BT-BY-L 조합
A9: NRY-05 | B9: 노량진 | C9: P5 | D9: 3:25~4:30 | E9: 폭풍 방파제 | F9: 압박 웨이브→보스 | G9: 추가89: W54·F7·P3·G1 | H9: 4:20 회복 | I9: 보스 부두 | J9: 5u | K9: 현재씬 매칭 확장 | L9: 보스축 5u·회복 포켓 1셀 확보
A10: HWY-01 | B10: 고속도로 | C10: P1 | D10: 0:00~0:40 | E10: 직선 본선 | F10: 차선 학습·소형 적 | G10: 가드레일·표지판 | H10: 없음 | I10: 속도감 확보 | J10: 7u | K10: 기존 씬 기반 제안 | L10: 중앙 사격축 확보
A11: HWY-02 | B11: 고속도로 | C11: P2 | D11: 0:40~1:25 | E11: 고가 커브 램프 | F11: 코너 압박 | G11: 셰브론·방음벽 | H11: 짧은 탄약 | I11: 램프 하강 | J11: 7u | K11: 기존 씬 기반 제안 | L11: 턴 전후 대형물 금지
A12: HWY-03 | B12: 고속도로 | C12: P3 | D12: 1:25~2:10 | E12: Y분기·차선 합류 | F12: 차량 사이 전투 | G12: 승용차·트럭·드럼통 | H12: 2:30 보급 | I12: 선택 차선 합류 | J12: 7u | K12: 기존 씬 기반 제안 | L12: 중앙 사격축 확보
A13: HWY-04 | B13: 고속도로 | C13: P4 | D13: 2:10~3:05 | E13: 톨게이트 접근 | F13: 차단봉·게이트 웨이브 | G13: 톨부스·신호등 | H13: 통과 직후 회복 | I13: 전자 톨게이트 | J13: 7u | K13: 기존 씬 기반 제안 | L13: 중앙 사격축 확보
A14: HWY-05 | B14: 고속도로 | C14: P5 | D14: 3:05~4:00 | E14: 터널·고가도로 | F14: 버스·트럭 매복 | G14: 터널·속도카메라 | H14: 3:45 탄약 | I14: 터널 출구 보스 | J14: 7u | K14: 기존 씬 기반 제안 | L14: 중앙 사격축 확보
A15: RST-01 | B15: 휴게소 | C15: P1 | D15: 0:00~0:25 | E15: 서비스 도로 진입 | F15: 저강도 정리 | G15: 휴게소 간판·볼라드 | H15: 회복 드롭 | I15: 건물 앞 진입 | J15: 6u | K15: 문서 기반 신규 제안 | L15: 중앙 사격축 확보
... A28: GNG-05 | B28: 백화점 | C28: P5 | D28: 3:50~5:00 | E28: 백화점 입구 | F28: 최종 보스 | G28: 자동문·다이아 조형물 | H28: 4:40 최종 보급 | I28: 최종 보상 | J28: 7u | K28: 문서 기반 신규 제안 | L28: 중앙 사격축 확보

Sheet 설정_계산
A1: 축척 검증 · 목표시간별 필요한 거리와 모듈
A2: 현재 코드는 전투 중에도 자동 전진합니다. 별도 정지 게이트가 없으면 목표시간은 도로 길이로 확보해야 하며, 1지도셀은 2모듈로 표시합니다.
A4: No | B4: 챕터 | C4: 목표(초) | D4: 표시 | E4: 이론 필요거리(u) | F4: 재시작 | G4: 총 모듈 | H4: 추가 모듈 | I4: 계획거리(u) | J4: 예상시간(초) | K4: 지도셀 | L4: 판정 | N4: 이동·축척 가정
A5: 1 | B5: 노량진 | C5: 270 | D5: =INT(C5/60)&":"&TEXT(MOD(C5,60),"00") -> 4:30 | E5: =IF(C5<=$O$8,$O$5*C5+0.5*$O$7*C5^2,$O$9+(C5-$O$8)*$O$6) -> 1580 | F5: 현재 챕터 | G5: =$O$12+ROUNDUP((E5-$O$11)/$O$10,0) -> 142 | H5: =G5-$O$12 -> 121 | I5: =$O$11+H5*$O$10 -> 1581.975 | J5: =IF(I5<=$O$9,(-$O$5+SQRT($O$5^2+2*$O$7*I5))/$O$7,$O$8+(I5-$O$9)/$O$6) -> 270.32917 | K5: =ROUNDUP(G5/$O$13,0) -> 71 | L5: =IF(ABS(J5-C5)<=2,"OK","재조정") -> OK | N5: 시작 속도 | O5: 4 | P5: u/s
A6: 2 | B6: 고속도로 | C6: 240 | D6: =INT(C6/60)&":"&TEXT(MOD(C6,60),"00") -> 4:00 | E6: =IF(C6<=$O$8,$O$5*C6+0.5*$O$7*C6^2,$O$9+(C6-$O$8)*$O$6) -> 1400 | F6: 현재 챕터 | G6: =ROUNDUP(E6/$O$10,0) -> 125 | H6: =G6 -> 125 | I6: =G6*$O$10 -> 1406.25 | J6: =IF(I6<=$O$9,(-$O$5+SQRT($O$5^2+2*$O$7*I6))/$O$7,$O$8+(I6-$O$9)/$O$6) -> 241.04167 | K6: =ROUNDUP(G6/$O$13,0) -> 63 | L6: =IF(ABS(J6-C6)<=2,"OK","재조정") -> OK | N6: 최대 속도 | O6: 6 | P6: u/s
A7: 3 | B7: 휴게소 | C7: 120 | D7: =INT(C7/60)&":"&TEXT(MOD(C7,60),"00") -> 2:00 | E7: =IF(C7<=$O$8,$O$5*C7+0.5*$O$7*C7^2,$O$9+(C7-$O$8)*$O$6) -> 680 | F7: 현재 챕터 | G7: =ROUNDUP(E7/$O$10,0) -> 61 | H7: =G7 -> 61 | I7: =G7*$O$10 -> 686.25 | J7: =IF(I7<=$O$9,(-$O$5+SQRT($O$5^2+2*$O$7*I7))/$O$7,$O$8+(I7-$O$9)/$O$6) -> 121.04167 | K7: =ROUNDUP(G7/$O$13,0) -> 31 | L7: =IF(ABS(J7-C7)<=2,"OK","재조정") -> OK | N7: 가속 | O7: 0.05 | P7: u/s²
A8: 4 | B8: 도심 | C8: 270 | D8: =INT(C8/60)&":"&TEXT(MOD(C8,60),"00") -> 4:30 | E8: =IF(C8<=$O$8,$O$5*C8+0.5*$O$7*C8^2,$O$9+(C8-$O$8)*$O$6) -> 1580 | F8: 현재 챕터 | G8: =ROUNDUP(E8/$O$10,0) -> 141 | H8: =G8 -> 141 | I8: =G8*$O$10 -> 1586.25 | J8: =IF(I8<=$O$9,(-$O$5+SQRT($O$5^2+2*$O$7*I8))/$O$7,$O$8+(I8-$O$9)/$O$6) -> 271.04167 | K8: =ROUNDUP(G8/$O$13,0) -> 71 | L8: =IF(ABS(J8-C8)<=2,"OK","재조정") -> OK | N8: 최대속도 도달 | O8: =(O6-O5)/O7 -> 40 | P8: s
A9: 5 | B9: 백화점 | C9: 300 | D9: =INT(C9/60)&":"&TEXT(MOD(C9,60),"00") -> 5:00 | E9: =IF(C9<=$O$8,$O$5*C9+0.5*$O$7*C9^2,$O$9+(C9-$O$8)*$O$6) -> 1760 | F9: 현재 챕터 | G9: =ROUNDUP(E9/$O$10,0) -> 157 | H9: =G9 -> 157 | I9: =G9*$O$10 -> 1766.25 | J9: =IF(I9<=$O$9,(-$O$5+SQRT($O$5^2+2*$O$7*I9))/$O$7,$O$8+(I9-$O$9)/$O$6) -> 301.04167 | K9: =ROUNDUP(G9/$O$13,0) -> 79 | L9: =IF(ABS(J9-C9)<=2,"OK","재조정") -> OK | N9: 가속구간 거리 | O9: =O5*O8+0.5*O7*O8^2 -> 200 | P9: u
A10: 합계 | B10: =COUNTA(B5:B9) -> 5 | C10: =SUM(C5:C9) -> 1200 | D10: =INT(C10/60)&":"&TEXT(MOD(C10,60),"00") -> 20:00 | E10: =SUM(E5:E9) -> 7000 | F10: 연속 플레이 아님 | G10: =SUM(G5:G9) -> 626 | H10: =SUM(H5:H9) -> 605 | I10: =SUM(I5:I9) -> 7026.975 | J10: =SUM(J5:J9) -> 1204.4958 | K10: =SUM(K5:K9) -> 315 | L10: =IF(COUNTIF(L5:L9,"<>OK")=0,"전체 OK","확인") -> 전체 OK | N10: 도로 모듈 길이 | O10: 11.25 | P10: u
N11: 노량진 기존거리 | O11: 220.72502 | P11: u
N12: 노량진 기존모듈 | O12: 21 | P12: 개
A13: 판정 | N13: 지도셀당 모듈 | O13: 2 | P13: 개
A14: 현재 노량진 21모듈·220.7u는 약 43.5초입니다. 사용자가 지적한 ‘약 1분’ 판단이 맞습니다.
A15: 4분30초 노량진은 총 142모듈·1,582.0u가 필요하므로 현재보다 121모듈을 추가해야 합니다.
A16: 전체 새 시간안은 20:00이며 계획 기준 626모듈·약 7,027u·지도셀 315개입니다.
A17: 전투 시간을 따로 더하지 않았습니다. 현재 PlayerScript는 게임 진행 중 계속 전진하므로 전투도 이동시간 안에 포함됩니다.
A18: 실제 Stage02~05 프리팹 길이가 11.25u와 다르면 각 스테이지 모듈 길이만 바꾸어 모듈 수를 다시 계산해야 합니다.

Sheet 자료_근거
A1: 읽기 전용 설계 근거
A2: Unity 씬과 맵툴은 수정하지 않았습니다. 아래 파일과 기존 설계 결과를 읽기 전용으로 참고했습니다.
A4: 구분 | B4: 챕터 | C4: 경로 | D4: 확인 내용 | E4: 설계 적용 | F4: 상태
A5: Unity 씬 | B5: 노량진 | C5: Assets/ShooterSurvival/Scenes/Tools/Noryangjin_MapTool_Mode.unity | D5: 현재 Roads 21개·빨간 원 시작 | E5: 기존 21개 전부 주행 | F5: 확인
A6: 기존 Excel | B6: 노량진 | C6: outputs/noryangjin_scene1_5min/노량진_씬1_빨간원시작_5분_확장_설계도.xlsx | D6: 158모듈·1761.98u·300.33초 | E6: CH.1 상세 수치 유지 | F6: 확인
A7: Unity 씬 | B7: 고속도로 | C7: Assets/ShooterSurvival/Scenes/Generated/Stage02_Highway_AutoDraft.unity | D7: 직선 본선·차선·코인·가드레일 | E7: 5분 확장 기준축 | F7: 확인
A8: 에셋 | B8: 고속도로 | C8: Assets/ShooterSurvival/Prefabs/MeshyAI/Stage02_Highway | D8: 톨게이트·터널·표지판·방음벽 | E8: P1~P5 랜드마크 | F8: 확인
A9: 설계 문서 | B9: 전체 | C9: docs/design/stage_reference_regeneration_prompts_20260515.md | D9: Stage01~05 구간별 시각 어휘 | E9: 챕터 동선·오브젝트 | F9: 확인
A10: 문서 인덱스 | B10: 전체 | C10: docs/README.md | D10: Stage01~05 활성 에셋 시퀀스 | E10: 구현 상태 구분 | F10: 확인
A11: 씬 확인 | B11: 휴게소·도심·백화점 | C11: Assets/ShooterSurvival/Scenes | D11: 현재 전용 씬 없음 | E11: 문서 기반 신규 제안으로 표시 | F11: 미구현
A12: 속도 데이터 | B12: 전체 | C12: Assets/StreamingAssets/Data.xlsx / 환경 변수 | D12: playerSpeed = 4, 6, 0.05 | E12: 거리 적분·목표 모듈 계산 | F12: 확인
A13: 이동 코드 | B13: 전체 | C13: Assets/ShooterSurvival/Scripts/Player/PlayerScript.cs | D13: 전투 중에도 FixedUpdate 자동 전진 | E13: 정지시간 제외·길이로 시간 확보 | F13: 확인
A14: 구분 원칙 • 실측 기반: 현재 Unity 씬/기존 계산으로 좌표·길이가 확인된 설계 • 기존 씬 기반 제안: 현재 AutoDraft 또는 에셋을 확장한 구조안 • 문서 기반 신규 제안: MapTool 제작 전에 사용할 레이아웃 가이드
A19: 구분 | B19: 대상 | C19: 상태 | D19: 읽은 값 | E19: 분석 방식 | F19: 반영 | G19: 주의 | H19: 일자
A20: 현재 Unity 씬 | B20: Noryangjin_MapTool_Mode | C20: dirty / read-only | D20: Roads 21 · Props 170 · 16 prefab types | E20: MCP active hierarchy + prefab path match | F20: 노량진 오브젝트 매칭·배치 2개 시트 | G20: Unity 씬 미수정 | H20: 2026-07-19

Sheet 고해상도_전체도
A1: 5개 챕터 20분 · 사용자 스케치 기준 직선·꺾임 전체도 4K
A2: 빨강 노량진 → 파랑 고속도로 → 초록 휴게소 → 주황 도심 → 보라 백화점. Unity/MapTool 수정 없이 설계도만 작성했습니다.
